Workbook

Sheet 目录
A1: 目录及链接 | D1: 各交易所交易规则链接
A2: 1 | B2: 目录 | D2: 中国金融期货交易所 | E2: http://www.cffex.com.cn/jysgz/
A3: 2 | B3: 交易时间表 | D3: 上海期货交易所 | E3: https://www.shfe.com.cn/regulation/
A4: 3 | B4: 期货合约要素 | D4: 上海国际能源交易中心 | E4: https://www.ine.cn/regulation/ineregulation/rules/
A5: 4 | B5: 期权合约要素 | D5: 大连商品交易所 | E5: http://www.dce.com.cn/dalianshangpin/fgfz/index.html
A6: 5 | B6: 保证金及涨跌停板幅度表 | D6: 郑州商品交易所 | E6: https://www.czce.com.cn/cn/flfg/H077005index_1.htm
A7: 6 | B7: 限仓规则 | D7: 广州期货交易所 | E7: http://www.gfex.com.cn/gfex/jysgz/lists_notime.shtml
A8: 7 | B8: 交易限额 | D8: 上海证券交易所 | E8: http://www.sse.com.cn/lawandrules/sselawsrules/option/
A9: 8 | B9: 单笔最小开仓手数 | D9: 深圳证券交易所 | E9: https://www.szse.cn/lawrules/rule/derivative/index.html
A10: 9 | B10: 异常交易规则
A11: 10 | B11: 保证金优惠规则
A12: 11 | B12: 指令规则
A13: 12 | B13: 期权行权规则
A14: 13 | B14: 申报费规则
A15: 14 | B15: 修订记录
A16: 免责说明：本文件为国泰君安期货有限公司根据目前交易所规则汇编，供您参考，如有相关规则变动，则以交易所最新发布为准。

Sheet 交易时间表
A1: 点此返回目录
B2: 期货及期权各品种交易时间表
B3: 交易所 | C3: 品种名称 | D3: 品种代码 | E3: 是否有期权 | F3: 交易时间 | J3: QFII&RQFII | K3: 国际化品种
F4: 夜盘集合竞价 | G4: 夜盘连续竞价 | H4: 日盘集合竞价 | I4: 日盘连续竞价
B5: 上期所 | C5: 线材 | D5: wr | F5: 无夜盘 | H5: 申报阶段8:55-8:59 撮合阶段8:59-9:00 | I5: 上午9:00-10:15 10:30-11:30 下午13:30-15:00 | J5: =IFERROR(IF(VLOOKUP(D5,期货合约要素!$D:$Q,12,0)=0,"",VLOOKUP(D5,期货合约要素!$D:$Q,12,0)),IF(VLOOKUP(D5,期权合约要素!$D:$V,17,0)=0,"",VLOOKUP(D5,期权合约要素!$D:$V,17,0))) | K5: =IFERROR(IF(VLOOKUP(D5,期货合约要素!$D:$Q,14,0)=0,"",VLOOKUP(D5,期货合约要素!$D:$Q,14,0)),IF(VLOOKUP(D5,期权合约要素!$D:$V,19,0)=0,"",VLOOKUP(D5,期权合约要素!$D:$V,19,0)))
C6: 螺纹钢 | D6: rb | E6: 是 | F6: 申报阶段20:55-20:59 撮合阶段20:59-21:00 | G6: 21：00-23：00 | H6: 二次集合竞价： 申报阶段8:55-8:59 撮合阶段8:59-9:00 备注：未成交的交易指令自动参与日盘集合竞价，投资者可以在日盘集合竞价申报阶段对夜盘交易时段未成交的指令进行撤单。 | J6: =IFERROR(IF(VLOOKUP(D6,期货合约要素!$D:$Q,12,0)=0,"",VLOOKUP(D6,期货合约要素!$D:$Q,12,0)),IF(VLOOKUP(D6,期权合约要素!$D:$V,17,0)=0,"",VLOOKUP(D6,期权合约要素!$D:$V,17,0))) -> √ | K6: =IFERROR(IF(VLOOKUP(D6,期货合约要素!$D:$Q,14,0)=0,"",VLOOKUP(D6,期货合约要素!$D:$Q,14,0)),IF(VLOOKUP(D6,期权合约要素!$D:$V,19,0)=0,"",VLOOKUP(D6,期权合约要素!$D:$V,19,0)))
C7: 热轧卷板 | D7: hc | J7: =IFERROR(IF(VLOOKUP(D7,期货合约要素!$D:$Q,12,0)=0,"",VLOOKUP(D7,期货合约要素!$D:$Q,12,0)),IF(VLOOKUP(D7,期权合约要素!$D:$V,17,0)=0,"",VLOOKUP(D7,期权合约要素!$D:$V,17,0))) -> √ | K7: =IFERROR(IF(VLOOKUP(D7,期货合约要素!$D:$Q,14,0)=0,"",VLOOKUP(D7,期货合约要素!$D:$Q,14,0)),IF(VLOOKUP(D7,期权合约要素!$D:$V,19,0)=0,"",VLOOKUP(D7,期权合约要素!$D:$V,19,0)))
C8: 燃料油 | D8: fu | E8: 是 | J8: =IFERROR(IF(VLOOKUP(D8,期货合约要素!$D:$Q,12,0)=0,"",VLOOKUP(D8,期货合约要素!$D:$Q,12,0)),IF(VLOOKUP(D8,期权合约要素!$D:$V,17,0)=0,"",VLOOKUP(D8,期权合约要素!$D:$V,17,0))) -> √ | K8: =IFERROR(IF(VLOOKUP(D8,期货合约要素!$D:$Q,14,0)=0,"",VLOOKUP(D8,期货合约要素!$D:$Q,14,0)),IF(VLOOKUP(D8,期权合约要素!$D:$V,19,0)=0,"",VLOOKUP(D8,期权合约要素!$D:$V,19,0)))
C9: 石油沥青 | D9: bu | E9: 是 | J9: =IFERROR(IF(VLOOKUP(D9,期货合约要素!$D:$Q,12,0)=0,"",VLOOKUP(D9,期货合约要素!$D:$Q,12,0)),IF(VLOOKUP(D9,期权合约要素!$D:$V,17,0)=0,"",VLOOKUP(D9,期权合约要素!$D:$V,17,0))) -> √ | K9: =IFERROR(IF(VLOOKUP(D9,期货合约要素!$D:$Q,14,0)=0,"",VLOOKUP(D9,期货合约要素!$D:$Q,14,0)),IF(VLOOKUP(D9,期权合约要素!$D:$V,19,0)=0,"",VLOOKUP(D9,期权合约要素!$D:$V,19,0)))
C10: 天然橡胶 | D10: ru | E10: 是 | J10: =IFERROR(IF(VLOOKUP(D10,期货合约要素!$D:$Q,12,0)=0,"",VLOOKUP(D10,期货合约要素!$D:$Q,12,0)),IF(VLOOKUP(D10,期权合约要素!$D:$V,17,0)=0,"",VLOOKUP(D10,期权合约要素!$D:$V,17,0))) -> √ | K10: =IFERROR(IF(VLOOKUP(D10,期货合约要素!$D:$Q,14,0)=0,"",VLOOKUP(D10,期货合约要素!$D:$Q,14,0)),IF(VLOOKUP(D10,期权合约要素!$D:$V,19,0)=0,"",VLOOKUP(D10,期权合约要素!$D:$V,19,0)))
C11: 丁二烯橡胶 | D11: br | E11: 是 | J11: =IFERROR(IF(VLOOKUP(D11,期货合约要素!$D:$Q,12,0)=0,"",VLOOKUP(D11,期货合约要素!$D:$Q,12,0)),IF(VLOOKUP(D11,期权合约要素!$D:$V,17,0)=0,"",VLOOKUP(D11,期权合约要素!$D:$V,17,0))) | K11: =IFERROR(IF(VLOOKUP(D11,期货合约要素!$D:$Q,14,0)=0,"",VLOOKUP(D11,期货合约要素!$D:$Q,14,0)),IF(VLOOKUP(D11,期权合约要素!$D:$V,19,0)=0,"",VLOOKUP(D11,期权合约要素!$D:$V,19,0)))
C12: 漂针浆 | D12: sp | E12: 是 | J12: =IFERROR(IF(VLOOKUP(D12,期货合约要素!$D:$Q,12,0)=0,"",VLOOKUP(D12,期货合约要素!$D:$Q,12,0)),IF(VLOOKUP(D12,期权合约要素!$D:$V,17,0)=0,"",VLOOKUP(D12,期权合约要素!$D:$V,17,0))) -> √ | K12: =IFERROR(IF(VLOOKUP(D12,期货合约要素!$D:$Q,14,0)=0,"",VLOOKUP(D12,期货合约要素!$D:$Q,14,0)),IF(VLOOKUP(D12,期权合约要素!$D:$V,19,0)=0,"",VLOOKUP(D12,期权合约要素!$D:$V,19,0)))
C13: 胶版印刷纸 | D13: op | E13: 是 | J13: =IFERROR(IF(VLOOKUP(D13,期货合约要素!$D:$Q,12,0)=0,"",VLOOKUP(D13,期货合约要素!$D:$Q,12,0)),IF(VLOOKUP(D13,期权合约要素!$D:$V,17,0)=0,"",VLOOKUP(D13,期权合约要素!$D:$V,17,0))) | K13: =IFERROR(IF(VLOOKUP(D13,期货合约要素!$D:$Q,14,0)=0,"",VLOOKUP(D13,期货合约要素!$D:$Q,14,0)),IF(VLOOKUP(D13,期权合约要素!$D:$V,19,0)=0,"",VLOOKUP(D13,期权合约要素!$D:$V,19,0)))
C14: 铝 | D14: al | E14: 是 | F14: 申报阶段20:55-20:59 撮合阶段20:59-21:00 | G14: 21：00-次日01：00 | J14: =IFERROR(IF(VLOOKUP(D14,期货合约要素!$D:$Q,12,0)=0,"",VLOOKUP(D14,期货合约要素!$D:$Q,12,0)),IF(VLOOKUP(D14,期权合约要素!$D:$V,17,0)=0,"",VLOOKUP(D14,期权合约要素!$D:$V,17,0))) -> √ | K14: =IFERROR(IF(VLOOKUP(D14,期货合约要素!$D:$Q,14,0)=0,"",VLOOKUP(D14,期货合约要素!$D:$Q,14,0)),IF(VLOOKUP(D14,期权合约要素!$D:$V,19,0)=0,"",VLOOKUP(D14,期权合约要素!$D:$V,19,0)))
C15: 铜 | D15: cu | E15: 是 | J15: =IFERROR(IF(VLOOKUP(D15,期货合约要素!$D:$Q,12,0)=0,"",VLOOKUP(D15,期货合约要素!$D:$Q,12,0)),IF(VLOOKUP(D15,期权合约要素!$D:$V,17,0)=0,"",VLOOKUP(D15,期权合约要素!$D:$V,17,0))) -> √ | K15: =IFERROR(IF(VLOOKUP(D15,期货合约要素!$D:$Q,14,0)=0,"",VLOOKUP(D15,期货合约要素!$D:$Q,14,0)),IF(VLOOKUP(D15,期权合约要素!$D:$V,19,0)=0,"",VLOOKUP(D15,期权合约要素!$D:$V,19,0)))
C16: 不锈钢 | D16: ss | J16: =IFERROR(IF(VLOOKUP(D16,期货合约要素!$D:$Q,12,0)=0,"",VLOOKUP(D16,期货合约要素!$D:$Q,12,0)),IF(VLOOKUP(D16,期权合约要素!$D:$V,17,0)=0,"",VLOOKUP(D16,期权合约要素!$D:$V,17,0))) -> √ | K16: =IFERROR(IF(VLOOKUP(D16,期货合约要素!$D:$Q,14,0)=0,"",VLOOKUP(D16,期货合约要素!$D:$Q,14,0)),IF(VLOOKUP(D16,期权合约要素!$D:$V,19,0)=0,"",VLOOKUP(D16,期权合约要素!$D:$V,19,0)))
C17: 锌 | D17: zn | E17: 是 | J17: =IFERROR(IF(VLOOKUP(D17,期货合约要素!$D:$Q,12,0)=0,"",VLOOKUP(D17,期货合约要素!$D:$Q,12,0)),IF(VLOOKUP(D17,期权合约要素!$D:$V,17,0)=0,"",VLOOKUP(D17,期权合约要素!$D:$V,17,0))) -> √ | K17: =IFERROR(IF(VLOOKUP(D17,期货合约要素!$D:$Q,14,0)=0,"",VLOOKUP(D17,期货合约要素!$D:$Q,14,0)),IF(VLOOKUP(D17,期权合约要素!$D:$V,19,0)=0,"",VLOOKUP(D17,期权合约要素!$D:$V,19,0)))
C18: 铅 | D18: pb | E18: 是 | J18: =IFERROR(IF(VLOOKUP(D18,期货合约要素!$D:$Q,12,0)=0,"",VLOOKUP(D18,期货合约要素!$D:$Q,12,0)),IF(VLOOKUP(D18,期权合约要素!$D:$V,17,0)=0,"",VLOOKUP(D18,期权合约要素!$D:$V,17,0))) -> √ | K18: =IFERROR(IF(VLOOKUP(D18,期货合约要素!$D:$Q,14,0)=0,"",VLOOKUP(D18,期货合约要素!$D:$Q,14,0)),IF(VLOOKUP(D18,期权合约要素!$D:$V,19,0)=0,"",VLOOKUP(D18,期权合约要素!$D:$V,19,0)))
C19: 镍 | D19: ni | E19: 是 | J19: =IFERROR(IF(VLOOKUP(D19,期货合约要素!$D:$Q,12,0)=0,"",VLOOKUP(D19,期货合约要素!$D:$Q,12,0)),IF(VLOOKUP(D19,期权合约要素!$D:$V,17,0)=0,"",VLOOKUP(D19,期权合约要素!$D:$V,17,0))) -> √ | K19: =IFERROR(IF(VLOOKUP(D19,期货合约要素!$D:$Q,14,0)=0,"",VLOOKUP(D19,期货合约要素!$D:$Q,14,0)),IF(VLOOKUP(D19,期权合约要素!$D:$V,19,0)=0,"",VLOOKUP(D19,期权合约要素!$D:$V,19,0))) -> √
C20: 锡 | D20: sn | E20: 是 | J20: =IFERROR(IF(VLOOKUP(D20,期货合约要素!$D:$Q,12,0)=0,"",VLOOKUP(D20,期货合约要素!$D:$Q,12,0)),IF(VLOOKUP(D20,期权合约要素!$D:$V,17,0)=0,"",VLOOKUP(D20,期权合约要素!$D:$V,17,0))) -> √ | K20: =IFERROR(IF(VLOOKUP(D20,期货合约要素!$D:$Q,14,0)=0,"",VLOOKUP(D20,期货合约要素!$D:$Q,14,0)),IF(VLOOKUP(D20,期权合约要素!$D:$V,19,0)=0,"",VLOOKUP(D20,期权合约要素!$D:$V,19,0)))
C21: 氧化铝 | D21: ao | E21: 是 | J21: =IFERROR(IF(VLOOKUP(D21,期货合约要素!$D:$Q,12,0)=0,"",VLOOKUP(D21,期货合约要素!$D:$Q,12,0)),IF(VLOOKUP(D21,期权合约要素!$D:$V,17,0)=0,"",VLOOKUP(D21,期权合约要素!$D:$V,17,0))) | K21: =IFERROR(IF(VLOOKUP(D21,期货合约要素!$D:$Q,14,0)=0,"",VLOOKUP(D21,期货合约要素!$D:$Q,14,0)),IF(VLOOKUP(D21,期权合约要素!$D:$V,19,0)=0,"",VLOOKUP(D21,期权合约要素!$D:$V,19,0)))
C22: 铸造铝合金 | D22: ad | E22: 是 | J22: =IFERROR(IF(VLOOKUP(D22,期货合约要素!$D:$Q,12,0)=0,"",VLOOKUP(D22,期货合约要素!$D:$Q,12,0)),IF(VLOOKUP(D22,期权合约要素!$D:$V,17,0)=0,"",VLOOKUP(D22,期权合约要素!$D:$V,17,0))) | K22: =IFERROR(IF(VLOOKUP(D22,期货合约要素!$D:$Q,14,0)=0,"",VLOOKUP(D22,期货合约要素!$D:$Q,14,0)),IF(VLOOKUP(D22,期权合约要素!$D:$V,19,0)=0,"",VLOOKUP(D22,期权合约要素!$D:$V,19,0)))
C23: 黄金 | D23: au | E23: 是 | F23: 申报阶段20:55-20:59 撮合阶段20:59-21:00 | G23: 21：00-次日02：30 | J23: =IFERROR(IF(VLOOKUP(D23,期货合约要素!$D:$Q,12,0)=0,"",VLOOKUP(D23,期货合约要素!$D:$Q,12,0)),IF(VLOOKUP(D23,期权合约要素!$D:$V,17,0)=0,"",VLOOKUP(D23,期权合约要素!$D:$V,17,0))) -> √ | K23: =IFERROR(IF(VLOOKUP(D23,期货合约要素!$D:$Q,14,0)=0,"",VLOOKUP(D23,期货合约要素!$D:$Q,14,0)),IF(VLOOKUP(D23,期权合约要素!$D:$V,19,0)=0,"",VLOOKUP(D23,期权合约要素!$D:$V,19,0)))
C24: 白银 | D24: ag | E24: 是 | J24: =IFERROR(IF(VLOOKUP(D24,期货合约要素!$D:$Q,12,0)=0,"",VLOOKUP(D24,期货合约要素!$D:$Q,12,0)),IF(VLOOKUP(D24,期权合约要素!$D:$V,17,0)=0,"",VLOOKUP(D24,期权合约要素!$D:$V,17,0))) -> √ | K24: =IFERROR(IF(VLOOKUP(D24,期货合约要素!$D:$Q,14,0)=0,"",VLOOKUP(D24,期货合约要素!$D:$Q,14,0)),IF(VLOOKUP(D24,期权合约要素!$D:$V,19,0)=0,"",VLOOKUP(D24,期权合约要素!$D:$V,19,0)))
B25: 能源中心 | C25: 原油 | D25: sc | E25: 是 | J25: =IFERROR(IF(VLOOKUP(D25,期货合约要素!$D:$Q,12,0)=0,"",VLOOKUP(D25,期货合约要素!$D:$Q,12,0)),IF(VLOOKUP(D25,期权合约要素!$D:$V,17,0)=0,"",VLOOKUP(D25,期权合约要素!$D:$V,17,0))) -> √ | K25: =IFERROR(IF(VLOOKUP(D25,期货合约要素!$D:$Q,14,0)=0,"",VLOOKUP(D25,期货合约要素!$D:$Q,14,0)),IF(VLOOKUP(D25,期权合约要素!$D:$V,19,0)=0,"",VLOOKUP(D25,期权合约要素!$D:$V,19,0))) -> √
C26: 低硫燃料油 | D26: lu | F26: 申报阶段20:55-20:59 撮合阶段20:59-21:00 | G26: 21：00-23：00 | J26: =IFERROR(IF(VLOOKUP(D26,期货合约要素!$D:$Q,12,0)=0,"",VLOOKUP(D26,期货合约要素!$D:$Q,12,0)),IF(VLOOKUP(D26,期权合约要素!$D:$V,17,0)=0,"",VLOOKUP(D26,期权合约要素!$D:$V,17,0))) -> √ | K26: =IFERROR(IF(VLOOKUP(D26,期货合约要素!$D:$Q,14,0)=0,"",VLOOKUP(D26,期货合约要素!$D:$Q,14,0)),IF(VLOOKUP(D26,期权合约要素!$D:$V,19,0)=0,"",VLOOKUP(D26,期权合约要素!$D:$V,19,0))) -> √
C27: 20号胶 | D27: nr | E27: 是 | J27: =IFERROR(IF(VLOOKUP(D27,期货合约要素!$D:$Q,12,0)=0,"",VLOOKUP(D27,期货合约要素!$D:$Q,12,0)),IF(VLOOKUP(D27,期权合约要素!$D:$V,17,0)=0,"",VLOOKUP(D27,期权合约要素!$D:$V,17,0))) -> √ | K27: =IFERROR(IF(VLOOKUP(D27,期货合约要素!$D:$Q,14,0)=0,"",VLOOKUP(D27,期货合约要素!$D:$Q,14,0)),IF(VLOOKUP(D27,期权合约要素!$D:$V,19,0)=0,"",VLOOKUP(D27,期权合约要素!$D:$V,19,0))) -> √
C28: 国际铜 | D28: bc | E28: 是 | F28: 申报阶段20:55-20:59 撮合阶段20:59-21:00 | G28: 21：00-次日01：00 | J28: =IFERROR(IF(VLOOKUP(D28,期货合约要素!$D:$Q,12,0)=0,"",VLOOKUP(D28,期货合约要素!$D:$Q,12,0)),IF(VLOOKUP(D28,期权合约要素!$D:$V,17,0)=0,"",VLOOKUP(D28,期权合约要素!$D:$V,17,0))) -> √ | K28: =IFERROR(IF(VLOOKUP(D28,期货合约要素!$D:$Q,14,0)=0,"",VLOOKUP(D28,期货合约要素!$D:$Q,14,0)),IF(VLOOKUP(D28,期权合约要素!$D:$V,19,0)=0,"",VLOOKUP(D28,期权合约要素!$D:$V,19,0))) -> √
C29: 集运指数（欧线） | D29: ec | F29: 无夜盘 | H29: 申报阶段8:55-8:59 撮合阶段8:59-9:00 | J29: =IFERROR(IF(VLOOKUP(D29,期货合约要素!$D:$Q,12,0)=0,"",VLOOKUP(D29,期货合约要素!$D:$Q,12,0)),IF(VLOOKUP(D29,期权合约要素!$D:$V,17,0)=0,"",VLOOKUP(D29,期权合约要素!$D:$V,17,0))) -> √ | K29: =IFERROR(IF(VLOOKUP(D29,期货合约要素!$D:$Q,14,0)=0,"",VLOOKUP(D29,期货合约要素!$D:$Q,14,0)),IF(VLOOKUP(D29,期权合约要素!$D:$V,19,0)=0,"",VLOOKUP(D29,期权合约要素!$D:$V,19,0))) -> √
B30: 大商所 | C30: 黄大豆1号 | D30: a | E30: 是 | F30: 申报阶段20:55-20:59 撮合阶段20:59-21:00 | G30: 21：00-23：00 | H30: 二次集合竞价： 申报阶段8:55-8:59 撮合阶段8:59-9:00 备注：未成交的交易指令自动参与日盘集合竞价，投资者可以在日盘集合竞价申报阶段对夜盘交易时段未成交的指令进行撤单。未触发的止损（盈）指令和套利交易指令不参与集合竞价撮合。 | I30: 上午9:00-10:15 10:30-11:30 下午13:30-15:00 | J30: =IFERROR(IF(VLOOKUP(D30,期货合约要素!$D:$Q,12,0)=0,"",VLOOKUP(D30,期货合约要素!$D:$Q,12,0)),IF(VLOOKUP(D30,期权合约要素!$D:$V,17,0)=0,"",VLOOKUP(D30,期权合约要素!$D:$V,17,0))) -> √ | K30: =IFERROR(IF(VLOOKUP(D30,期货合约要素!$D:$Q,14,0)=0,"",VLOOKUP(D30,期货合约要素!$D:$Q,14,0)),IF(VLOOKUP(D30,期权合约要素!$D:$V,19,0)=0,"",VLOOKUP(D30,期权合约要素!$D:$V,19,0))) -> √
C31: 黄大豆2号 | D31: b | E31: 是 | J31: =IFERROR(IF(VLOOKUP(D31,期货合约要素!$D:$Q,12,0)=0,"",VLOOKUP(D31,期货合约要素!$D:$Q,12,0)),IF(VLOOKUP(D31,期权合约要素!$D:$V,17,0)=0,"",VLOOKUP(D31,期权合约要素!$D:$V,17,0))) -> √ | K31: =IFERROR(IF(VLOOKUP(D31,期货合约要素!$D:$Q,14,0)=0,"",VLOOKUP(D31,期货合约要素!$D:$Q,14,0)),IF(VLOOKUP(D31,期权合约要素!$D:$V,19,0)=0,"",VLOOKUP(D31,期权合约要素!$D:$V,19,0))) -> √
C32: 豆粕 | D32: m | E32: 是 | J32: =IFERROR(IF(VLOOKUP(D32,期货合约要素!$D:$Q,12,0)=0,"",VLOOKUP(D32,期货合约要素!$D:$Q,12,0)),IF(VLOOKUP(D32,期权合约要素!$D:$V,17,0)=0,"",VLOOKUP(D32,期权合约要素!$D:$V,17,0))) -> √ | K32: =IFERROR(IF(VLOOKUP(D32,期货合约要素!$D:$Q,14,0)=0,"",VLOOKUP(D32,期货合约要素!$D:$Q,14,0)),IF(VLOOKUP(D32,期权合约要素!$D:$V,19,0)=0,"",VLOOKUP(D32,期权合约要素!$D:$V,19,0))) -> √
C33: 豆油 | D33: y | E33: 是 | J33: =IFERROR(IF(VLOOKUP(D33,期货合约要素!$D:$Q,12,0)=0,"",VLOOKUP(D33,期货合约要素!$D:$Q,12,0)),IF(VLOOKUP(D33,期权合约要素!$D:$V,17,0)=0,"",VLOOKUP(D33,期权合约要素!$D:$V,17,0))) -> √ | K33: =IFERROR(IF(VLOOKUP(D33,期货合约要素!$D:$Q,14,0)=0,"",VLOOKUP(D33,期货合约要素!$D:$Q,14,0)),IF(VLOOKUP(D33,期权合约要素!$D:$V,19,0)=0,"",VLOOKUP(D33,期权合约要素!$D:$V,19,0))) -> √
C34: 棕榈油 | D34: p | E34: 是 | J34: =IFERROR(IF(VLOOKUP(D34,期货合约要素!$D:$Q,12,0)=0,"",VLOOKUP(D34,期货合约要素!$D:$Q,12,0)),IF(VLOOKUP(D34,期权合约要素!$D:$V,17,0)=0,"",VLOOKUP(D34,期权合约要素!$D:$V,17,0))) -> √ | K34: =IFERROR(IF(VLOOKUP(D34,期货合约要素!$D:$Q,14,0)=0,"",VLOOKUP(D34,期货合约要素!$D:$Q,14,0)),IF(VLOOKUP(D34,期权合约要素!$D:$V,19,0)=0,"",VLOOKUP(D34,期权合约要素!$D:$V,19,0))) -> √
C35: 玉米 | D35: c | E35: 是 | J35: =IFERROR(IF(VLOOKUP(D35,期货合约要素!$D:$Q,12,0)=0,"",VLOOKUP(D35,期货合约要素!$D:$Q,12,0)),IF(VLOOKUP(D35,期权合约要素!$D:$V,17,0)=0,"",VLOOKUP(D35,期权合约要素!$D:$V,17,0))) | K35: =IFERROR(IF(VLOOKUP(D35,期货合约要素!$D:$Q,14,0)=0,"",VLOOKUP(D35,期货合约要素!$D:$Q,14,0)),IF(VLOOKUP(D35,期权合约要素!$D:$V,19,0)=0,"",VLOOKUP(D35,期权合约要素!$D:$V,19,0)))
C36: 玉米淀粉 | D36: cs | E36: 是 | J36: =IFERROR(IF(VLOOKUP(D36,期货合约要素!$D:$Q,12,0)=0,"",VLOOKUP(D36,期货合约要素!$D:$Q,12,0)),IF(VLOOKUP(D36,期权合约要素!$D:$V,17,0)=0,"",VLOOKUP(D36,期权合约要素!$D:$V,17,0))) | K36: =IFERROR(IF(VLOOKUP(D36,期货合约要素!$D:$Q,14,0)=0,"",VLOOKUP(D36,期货合约要素!$D:$Q,14,0)),IF(VLOOKUP(D36,期权合约要素!$D:$V,19,0)=0,"",VLOOKUP(D36,期权合约要素!$D:$V,19,0)))
C37: 聚氯乙烯 | D37: v | E37: 是 | J37: =IFERROR(IF(VLOOKUP(D37,期货合约要素!$D:$Q,12,0)=0,"",VLOOKUP(D37,期货合约要素!$D:$Q,12,0)),IF(VLOOKUP(D37,期权合约要素!$D:$V,17,0)=0,"",VLOOKUP(D37,期权合约要素!$D:$V,17,0))) -> √ | K37: =IFERROR(IF(VLOOKUP(D37,期货合约要素!$D:$Q,14,0)=0,"",VLOOKUP(D37,期货合约要素!$D:$Q,14,0)),IF(VLOOKUP(D37,期权合约要素!$D:$V,19,0)=0,"",VLOOKUP(D37,期权合约要素!$D:$V,19,0)))
C38: 聚氯乙烯月均价 | D38: v_f | J38: =IFERROR(IF(VLOOKUP(D38,期货合约要素!$D:$Q,12,0)=0,"",VLOOKUP(D38,期货合约要素!$D:$Q,12,0)),IF(VLOOKUP(D38,期权合约要素!$D:$V,17,0)=0,"",VLOOKUP(D38,期权合约要素!$D:$V,17,0))) -> √ | K38: =IFERROR(IF(VLOOKUP(D38,期货合约要素!$D:$Q,14,0)=0,"",VLOOKUP(D38,期货合约要素!$D:$Q,14,0)),IF(VLOOKUP(D38,期权合约要素!$D:$V,19,0)=0,"",VLOOKUP(D38,期权合约要素!$D:$V,19,0)))
C39: 聚丙烯 | D39: pp | E39: 是 | J39: =IFERROR(IF(VLOOKUP(D39,期货合约要素!$D:$Q,12,0)=0,"",VLOOKUP(D39,期货合约要素!$D:$Q,12,0)),IF(VLOOKUP(D39,期权合约要素!$D:$V,17,0)=0,"",VLOOKUP(D39,期权合约要素!$D:$V,17,0))) -> √ | K39: =IFERROR(IF(VLOOKUP(D39,期货合约要素!$D:$Q,14,0)=0,"",VLOOKUP(D39,期货合约要素!$D:$Q,14,0)),IF(VLOOKUP(D39,期权合约要素!$D:$V,19,0)=0,"",VLOOKUP(D39,期权合约要素!$D:$V,19,0)))
C40: 聚丙烯月均价 | D40: pp_f | J40: =IFERROR(IF(VLOOKUP(D40,期货合约要素!$D:$Q,12,0)=0,"",VLOOKUP(D40,期货合约要素!$D:$Q,12,0)),IF(VLOOKUP(D40,期权合约要素!$D:$V,17,0)=0,"",VLOOKUP(D40,期权合约要素!$D:$V,17,0))) -> √ | K40: =IFERROR(IF(VLOOKUP(D40,期货合约要素!$D:$Q,14,0)=0,"",VLOOKUP(D40,期货合约要素!$D:$Q,14,0)),IF(VLOOKUP(D40,期权合约要素!$D:$V,19,0)=0,"",VLOOKUP(D40,期权合约要素!$D:$V,19,0)))
...

Sheet 期货合约要素
A1: 点此返回目录
B2: 期货品种合约要素
B3: 交易所 | C3: 品种名称 | D3: 品种代码 | E3: 交易单位(每手) | F3: 最小变动价位 | G3: 限价指令每次最大下单数量(手) | H3: 市价指令每次最大下单数量(手) | I3: 合约月份 | J3: 最小交割单位(手) | K3: 临近交割月调整要求 | L3: 最后交易日 | M3: 自然人最后退出日 | N3: 上市时间 | O3: QFII&RQFII | P3: QFII&RQFII可交易日期 | Q3: 国际化品种
B4: 中国金融期货交易所 | C4: 沪深300指数期货 | D4: IF | E4: 每点300元 | F4: 0.2点 | G4: 20 | H4: 10 （仅当月、下月合约支持） | I4: 当月、下月及随后两个季月 | J4: 1 | K4: 无需调整 | L4: 合约到期月份第三个周五 | M4: 无 | N4: 40284 | O4: √ | P4: 2011.05.04
C5: 上证50指数期货 | D5: IH | E5: 每点300元 | F5: 0.2点 | G5: 20 | H5: 10 （仅当月、下月合约支持） | I5: 当月、下月及随后两个季月 | J5: 1 | K5: 无需调整 | L5: 合约到期月份第三个周五 | M5: 无 | N5: 42110 | O5: √ | P5: 2015.04.16
C6: 中证500指数期货 | D6: IC | E6: 每点200元 | F6: 0.2点 | G6: 20 | H6: 10 （仅当月、下月合约支持） | I6: 当月、下月及随后两个季月 | J6: 1 | K6: 无需调整 | L6: 合约到期月份第三个周五 | M6: 无 | N6: 42110 | O6: √ | P6: 2015.04.16
C7: 中证1000指数期货 | D7: IM | E7: 每点200元 | F7: 0.2点 | G7: 20 | H7: 10 （仅当月、下月合约支持） | I7: 当月、下月及随后两个季月 | J7: 1 | K7: 无需调整 | L7: 合约到期月份第三个周五 | M7: 无 | N7: 44764 | O7: √ | P7: 2022.07.22
C8: 2年期国债期货 | D8: TS | E8: 合约乘数为20000 | F8: 0.002元 | G8: 50 | H8: 30 （ 仅最近的季月合约支持） | I8: 最近的三个季月（3月、6月、9月、12月中的最近三个月循环 | J8: 1 | K8: 未通过我司向交易所进行国债托管账户报备的客户需要在交割月前两个交易日收盘时将净持仓调整为0 | L8: 合约到期月份第二个周五 | M8: 未通过我司向交易所进行国债托管账户报备的客户需要在交割月前两个交易日收盘时将净持仓调整为0 | N8: 43329 | O8: √ | P8: 2026.04.24
C9: 5年期国债期货 | D9: TF | E9: 合约乘数为10000 | F9: 0.005元 | G9: 50 | H9: 30 （ 仅最近的季月合约支持） | I9: 最近的三个季月（3月、6月、9月、12月中的最近三个月循环 | J9: 1 | K9: 未通过我司向交易所进行国债托管账户报备的客户需要在交割月前两个交易日收盘时将净持仓调整为0 | L9: 合约到期月份第二个周五 | M9: 未通过我司向交易所进行国债托管账户报备的客户需要在交割月前两个交易日收盘时将净持仓调整为0 | N9: 41523 | O9: √ | P9: 2026.04.24
C10: 10年期国债期货 | D10: T | E10: 合约乘数为10000 | F10: 0.005元 | G10: 50 | H10: 30 （ 仅最近的季月合约支持） | I10: 最近的三个季月（3月、6月、9月、12月中的最近三个月循环 | J10: 1 | K10: 未通过我司向交易所进行国债托管账户报备的客户需要在交割月前两个交易日收盘时将净持仓调整为0 | L10: 合约到期月份第二个周五 | M10: 未通过我司向交易所进行国债托管账户报备的客户需要在交割月前两个交易日收盘时将净持仓调整为0 | N10: 42083 | O10: √ | P10: 2026.04.24
C11: 30年期国债期货 | D11: TL | E11: 合约乘数为10000 | F11: 0.01元 | G11: 50 | H11: 30 （ 仅最近的季月合约支持） | I11: 最近的三个季月（3月、6月、9月、12月中的最近三个月循环 | J11: 1 | K11: 未通过我司向交易所进行国债托管账户报备的客户需要在交割月前两个交易日收盘时将净持仓调整为0 | L11: 合约到期月份第二个周五 | M11: 未通过我司向交易所进行国债托管账户报备的客户需要在交割月前两个交易日收盘时将净持仓调整为0 | N11: 45037 | O11: √ | P11: 2026.04.24
B12: 上海国际能源交易中心 | C12: 原油 | D12: sc | E12: 1000桶 | F12: 0.1元/桶 | G12: 500 | H12: 60 | I12: 最近1-12个月为连续月份以及随后八个季月 | J12: 1 | K12: 无需调整 | L12: 交割月份前第一月的最后一个交易日 | M12: 最后交易日前第8个交易日收盘时调整为0手 | N12: 43185 | O12: √ | P12: 2022.09.05 | Q12: √
C13: 20号胶 | D13: nr | E13: 10吨 | F13: 5元/吨 | G13: 500 | H13: 60 | I13: 1-12月 | J13: 10 | K13: 10手整数倍 | L13: 合约交割月份的15日 | M13: 最后交易日前第5个交易日收盘时调整为0手 | N13: 43689 | O13: √ | P13: 2022.09.05 | Q13: √
C14: 低硫燃料油 | D14: lu | E14: 10吨 | F14: 1元/吨 | G14: 500 | H14: 60 | I14: 1-12月 | J14: 1 | K14: 无需调整 | L14: 交割月份前第一月的最后一个交易日 | M14: 最后交易日前第5个交易日收盘时调整为0手 | N14: 44004 | O14: √ | P14: 2022.09.05 | Q14: √
C15: 国际铜 | D15: bc | E15: 5吨 | F15: 10元/吨 | G15: 500 | H15: 60 | I15: 1-12月 | J15: 5 | K15: 5手整数倍 | L15: 合约交割月份的15日 | M15: 最后交易日前第5个交易日收盘时调整为0手 | N15: 44154 | O15: √ | P15: 2022.09.05 | Q15: √
C16: 集运指数（欧线） | D16: ec | E16: 每点50元 | F16: 0.5点 | G16: 500 | H16: 60 | I16: 1、3、4、5、6、7、8、9、10、11、12月份中的最近6个月内连续月份及随后的两个季月 | J16: 1 | K16: 无需调整 | L16: 合约交割月份最后一个开展期货交易的周一 | M16: 无需调整 | N16: 45156 | O16: √ | P16: 2025.03.04 | Q16: √
B17: 上海期货交易所 | C17: 螺纹钢 | D17: rb | E17: 10 吨 | F17: 1元/吨 | G17: 500 | H17: 60 | I17: 1-12月 | J17: 30 | K17: 30手整数倍 | L17: 合约交割月份的15日 | M17: 最后交易日前第5个交易日收盘时调整为0手 | N17: 39899 | O17: √ | P17: 2022.09.05
C18: 热轧卷板 | D18: hc | E18: 10 吨 | F18: 1元/吨 | G18: 500 | H18: 60 | I18: 1-12月 | J18: 30 | K18: 30手整数倍 | L18: 合约交割月份的15日 | M18: 最后交易日前第5个交易日收盘时调整为0手 | N18: 41719 | O18: √ | P18: 2022.09.05
C19: 线材 | D19: wr | E19: 10 吨 | F19: 1元/吨 | G19: 500 | H19: 60 | I19: 1-12月 | J19: 30 | K19: 30手整数倍 | L19: 合约交割月份的15日 | M19: 最后交易日前第5个交易日收盘时调整为0手 | N19: 39899 | P19: ——
C20: 铜 | D20: cu | E20: 5 吨 | F20: 10元/吨 | G20: 500 | H20: 60 | I20: 1-12月 | J20: 5 | K20: 5手整数倍 | L20: 合约交割月份的15日 | M20: 最后交易日前第5个交易日收盘时调整为0手 | N20: 34029 | O20: √ | P20: 2022.09.05
C21: 铝 | D21: al | E21: 5 吨 | F21: 5元/吨 | G21: 500 | H21: 60 | I21: 1-12月 | J21: 5 | K21: 5手整数倍 | L21: 合约交割月份的15日 | M21: 最后交易日前第5个交易日收盘时调整为0手 | N21: 33752 | O21: √ | P21: 2022.09.05
C22: 锌 | D22: zn | E22: 5 吨 | F22: 5元/吨 | G22: 500 | H22: 60 | I22: 1-12月 | J22: 5 | K22: 5手整数倍 | L22: 合约交割月份的15日 | M22: 最后交易日前第5个交易日收盘时调整为0手 | N22: 39167 | O22: √ | P22: 2022.09.05
C23: 铅 | D23: pb | E23: 5 吨 | F23: 5元/吨 | G23: 500 | H23: 60 | I23: 1-12月 | J23: 5 | K23: 5手整数倍 | L23: 合约交割月份的15日 | M23: 最后交易日前第5个交易日收盘时调整为0手 | N23: 40626 | O23: √ | P23: 2025.06.20
C24: 氧化铝 | D24: ao | E24: 20吨 | F24: 1元/吨 | G24: 500 | H24: 60 | I24: 1-12月 | J24: 15 | K24: 15手的整数倍 | L24: 合约交割月份的15日 | M24: 最后交易日前第5个交易日收盘时调整为0手 | N24: 45096 | P24: ——
C25: 不锈钢 | D25: ss | E25: 5吨 | F25: 5元/吨 | G25: 500 | H25: 60 | I25: 1-12月 | J25: 12 | K25: 12手的整数倍 | L25: 合约交割月份的15日 | M25: 最后交易日前第5个交易日收盘时调整为0手 | N25: 43733 | O25: √ | P25: 2025.03.04
C26: 镍 | D26: ni | E26: 1吨 | F26: 10元/吨 | G26: 500 | H26: 60 | I26: 1-12月 | J26: 6 | K26: 6手的整数倍 | L26: 合约交割月份的15日 | M26: 最后交易日前第5个交易日收盘时调整为0手 | N26: 42090 | O26: √ | P26: 2026.04.22 | Q26: √
C27: 锡 | D27: sn | E27: 1吨 | F27: 10元/吨 | G27: 500 | H27: 60 | I27: 1-12月 | J27: 2 | K27: 2手的整数倍 | L27: 合约交割月份的15日 | M27: 最后交易日前第5个交易日收盘时调整为0手 | N27: 42090 | O27: √ | P27: 2025.06.20
C28: 黄金 | D28: au | E28: 1000 克 | F28: 0.02元/克 | G28: 500 | H28: 60 | I28: 最近三个连续月份以及最近13个月以内的双月合约 | J28: 3 | K28: 3手整数倍 | L28: 合约交割月份的15日 | M28: 最后交易日前第5个交易日收盘时调整为0手 | N28: 39456 | O28: √ | P28: 2022.09.05
C29: 白银 | D29: ag | E29: 15千克 | F29: 1元/千克 | G29: 500 | H29: 60 | I29: 1-12月 | J29: 2 | K29: 2手整数倍 | L29: 合约交割月份的15日 | M29: 最后交易日前第5个交易日收盘时调整为0手 | N29: 41039 | O29: √ | P29: 2022.09.05
C30: 天然橡胶 | D30: ru | E30: 10吨 | F30: 5元/吨 | G30: 500 | H30: 60 | I30: 1、3-11月 | J30: 1 | K30: 无需调整 | L30: 合约交割月份的15日 | M30: 最后交易日前第5个交易日收盘时调整为0手 | N30: 34055 | O30: √ | P30: 2025.06.20
C31: 石油沥青 | D31: bu | E31: 10吨 | F31: 1元/吨 | G31: 500 | H31: 60 | I31: 最近1~12个月为连续月份以及随后四个季月 | J31: 1 | K31: 无需调整 | L31: 合约交割月份的15日 | M31: 最后交易日前第5个交易日收盘时调整为0手 | N31: 41556 | O31: √ | P31: 2025.09.10
C32: 纸浆 | D32: sp | E32: 10吨 | F32: 2元/吨 | G32: 500 | H32: 60 | I32: 1-12月 | J32: 2 | K32: 2手整数倍 | L32: 合约交割月份的15日 | M32: 最后交易日前第5个交易日收盘时调整为0手 | N32: 43431 | O32: √ | P32: 2025.03.04
C33: 保税380燃料油 | D33: fu | E33: 10吨 | F33: 1元/吨 | G33: 500 | H33: 60 | I33: 1-12月 | J33: 1 | K33: 无需调整 | L33: 交割月前一月的最后一个交易日 | M33: 最后交易日前第5个交易日收盘时调整为0手 | N33: 38224 | O33: √ | P33: 2025.03.04
C34: 合成橡胶 | D34: br | E34: 5吨 | F34: 5元/吨 | G34: 500 | H34: 60 | I34: 1-12月 | J34: 2 | K34: 2手整数倍 | L34: 合约交割月份的15日 | M34: 最后交易日前第5个交易日收盘时调整为0手 | N34: 45135 | P34: ——
C35: 铸造铝合金 | D35: ad | E35: 10吨 | F35: 5元/吨 | G35: 500 | H35: 60 | I35: 1-12月 | J35: 3 | K35: 3手整数倍 | L35: 合约交割月份的15日 | M35: 最后交易日前第5个交易日收盘时调整为0手 | N35: 45818 | P35: ——
C36: 胶版印刷纸 | D36: op | E36: 40吨 | F36: 2元/吨 | G36: 500 | H36: 60 | I36: 1-12月 | J36: 1 | K36: 无需调整 | L36: 合约交割月份的15日 | M36: 最后交易日前第5个交易日收盘时调整为0手 | N36: 45910 | P36: ——
B37: 大连商品交易所 | C37: 黄大豆一号 | D37: a | E37: 10 吨 | F37: 1 元/吨 | G37: 1000 | H37: 1000 | I37: 1、3、5、7、9、11 月 | J37: 1 | K37: 自然人不能持仓进入交割月 | L37: 合约月份第 10 个交易日 | M37: 自然人不能持仓进入交割月 | N37: 37330 | O37: √ | P37: 2022.09.05 | Q37: √
C38: 黄大豆二号 | D38: b | E38: 10 吨 | F38: 1 元/吨 | G38: 1000 | H38: 1000 | I38: 1-12月 | J38: 100 | K38: 自然人不能持仓进入交割月 | L38: 合约月份第 10 个交易日 | M38: 自然人不能持仓进入交割月 | N38: 38343 | O38: √ | P38: 2022.09.05 | Q38: √
C39: 豆粕 | D39: m | E39: 10 吨 | F39: 1 元/吨 | G39: 1000 | H39: 1000 | I39: 1、3、5、7、8、9、11、12月 | J39: 1 | K39: 自然人不能持仓进入交割月 | L39: 合约月份第 10 个交易日 | M39: 自然人不能持仓进入交割月 | N39: 36724 | O39: √ | P39: 2022.09.05 | Q39: √
C40: 豆油 | D40: y | E40: 10 吨 | F40: 1 元/吨 （20260410交易时起生效） | G40: 1000 | H40: 1000 | I40: 1、3、5、7、8、9、11、12月 | J40: 1 | K40: 自然人不能持仓进入交割月 | L40: 合约月份第 10 个交易日 | M40: 自然人不能持仓进入交割月 | N40: 38726 | O40: √ | P40: 2022.09.05 | Q40: √
...

Sheet 期权合约要素
A1: 点此返回目录
B2: 期权品种合约要素
B3: 交易所 | C3: 品种名称 | D3: 品种代码 | E3: 合约标的 | F3: 夜盘交易时间 | G3: 总保证金比例 | H3: 保证金计算公式 | I3: 涨跌幅度 (标准) | J3: 交易单位 (每手) | K3: 最小变动价位 | L3: 限价指令每次最大下单数量(手) | M3: 市价指令每次最大下单数量(手) | N3: 合约月份 | O3: 最后交易日 | P3: 交收日 | Q3: 行权方式 | R3: 交割方式 | S3: 上市时间 | T3: QFII&RQFII | U3: QFII&RQFII可交易日期 | V3: 国际化品种
B4: 中金所 | C4: 沪深300指数期权 | D4: IO | E4: 沪深300指数 | F4: 无 | G4: 期权卖方交易保证金中涉及的合约保证金调整系数为14%，最低保障系数为0.5 | H4: 看涨期权：（合约结算价×合约乘数）+MAX（标的指数收盘价×合约乘数×12%-虚值额，0.5×标的指数收盘价×合约乘数×12%）； 看跌期权：（合约结算价×合约乘数）+MAX（标的指数收盘价×合约乘数×12%-虚值额，0.5×合约行权价格×合约乘数×12%） | I4: 上一交易日标的指数收盘价的±10% | J4: 100 | K4: 0.2点 | L4: 20 | M4: 无市价 | N4: 当月、下2个月及随后3个季月 | O4: 合约到期月份的第三个星期五 | P4: 同最后交易日 | Q4: 欧式 | R4: 现金 | S4: 43822 | T4: √ | U4: 2022.09.05
C5: 中证1000指数期权 | D5: MO | E5: 中证1000指数 | F5: 无 | J5: 100 | K5: 0.2点 | L5: 20 | M5: 无市价 | N5: 当月、下2个月及随后3个季月 | S5: 44764 | T5: √ | U5: 2022.09.05
C6: 上证50指数期权 | D6: HO | E6: 上证50指数 | F6: 无 | J6: 100 | K6: 0.2点 | L6: 20 | M6: 无市价 | N6: 当月、下2个月及随后3个季月 | S6: 44914 | T6: √ | U6: 2022.12.19
B7: 能源中心 | C7: 原油期权 | D7: sc_o | E7: 原油期货合约 | F7: 21:00-02:30 | G7: 期权卖方交易保证金中涉及标的期货合约的公司交易保证金收取标准为同期货保证金率 | H7: 期权合约结算价×标的期货合约交易单位+MAX[标的期货合约交易所保证金－（1/2）×期权虚值额，（1/2）×标的期货合约交易所保证金] | I7: 与期货合约涨跌停板幅度相同 | J7: 1000桶 | K7: 0.05元/桶 | L7: 100 | M7: 30 | N7: 最近两个连续月份合约，其后月份在标的期货合约结算后持仓量达到一定数值之后的第二个交易日挂牌。具体数值交易所另行发布。 | O7: 标的期货合约交割月前第一月的倒数第13个交易日 | P7: 同最后交易日 | Q7: 美式 | R7: 实物 | S7: 44368 | T7: √ | U7: 2022.09.05 | V7: √
C8: 20号胶期权 | D8: nr_o | E8: 20号胶期货合约 | F8: 21:00-23:00 | J8: 10吨 | K8: 1元/吨 | L8: 100 | M8: 30 | N8: 最近两个连续月份合约，其后月份在标的期货合约结算后持仓量达到一定数值之后的第二个交易日挂盘，具体数值交易所另行发布。 | O8: 标的期货合约交割月前第一月的倒数第五个交易日 | P8: 同最后交易日 | Q8: 美式 | R8: 实物 | S8: 46134 | T8: √ | U8: 2026.4.22 | V8: √
C9: 国际铜期权 | D9: bc_o | E9: 国际铜期货合约 | F9: 21:00-01:00 | J9: 5吨 | K9: 2元/吨 | L9: 100 | M9: 30 | N9: 最近两个连续月份合约，其后月份在标的期货合约结算后持仓量达到一定数值之后的第二个交易日挂盘，具体数值交易所另行发布。 | P9: 同最后交易日 | Q9: 美式 | R9: 实物 | S9: 46134 | T9: √ | U9: 2026.4.22 | V9: √
B10: 上期所 | C10: 铜期权 | D10: cu_o | E10: 铜期货合约 | F10: 21:00-01:00 | J10: 5 吨 | K10: 2元/吨 | L10: 100 | M10: 30 | N10: 1-12月；最近两个连续月份合约，其后月份在标的期货合约结算后持仓量达到一定数值之后的第二个交易日挂牌。具体数值交易所另行发布。 | O10: 标的期货合约交割月份前一个月的倒数第五个交易日 | P10: 同最后交易日 | Q10: 美式 | R10: 实物 | S10: 43364 | T10: √ | U10: 2022.09.05
C11: 天然橡胶期权 | D11: ru_o | E11: 天然橡胶期货合约 | F11: 21:00-23:00 | J11: 10吨 | K11: 1 元/吨 | L11: 100 | M11: 30 | N11: 1、3—11月；最近两个连续月份合约，其后月份在标的期货合约结算后持仓量达到一定数值之后的第二个交易日挂牌。具体数值交易所另行发布。 | S11: 43493 | T11: √ | U11: 2025.06.20
C12: 黄金期权 | D12: au_o | E12: 黄金期货合约 | F12: 21:00-02:30 | J12: 1000 克 | K12: 0.02元/克 | L12: 100 | M12: 30 | N12: 最近两个连续月份合约，其后月份在标的期货合约结算后持仓量达到一定数值之后的第二个交易日挂牌。具体数值交易所另行发布。 | S12: 43819 | T12: √ | U12: 2022.09.05
C13: 铝期权 | D13: al_o | E13: 铝期货合约 | F13: 21:00-01:00 | J13: 5 吨 | K13: 1元/吨 | L13: 100 | M13: 30 | N13: 最近两个连续月份合约，其后月份在标的期货合约结算后持仓量达到一定数值之后的第二个交易日挂牌。合约月份涉及的标的期货持仓量阈值为15000手（单边） | S13: 44053 | T13: √ | U13: 2022.09.05
C14: 锌期权 | D14: zn_o | E14: 锌期货合约 | F14: 21:00-01:00 | J14: 5 吨 | K14: 1元/吨 | L14: 100 | M14: 30 | N14: 最近两个连续月份合约，其后月份在标的期货合约结算后持仓量达到一定数值之后的第二个交易日挂牌。合约月份涉及的标的期货持仓量阈值为10000手（单边） | S14: 44053 | T14: √ | U14: 2022.09.05
C15: 螺纹钢期权 | D15: rb_o | E15: 螺纹钢期货合约 | F15: 21:00-23:00 | J15: 10吨 | K15: 0.5元/吨 | L15: 100 | M15: 30 | N15: 最近两个连续月份合约，其后月份在标的期货合约结算后持仓量达到一定数值之后的第二个交易日挂牌。合约月份涉及的标的期货持仓量阈值为100000手（单边） | S15: 44921 | T15: √ | U15: 2025.03.04
C16: 白银期权 | D16: ag_o | E16: 白银期货合约 | F16: 21:00-02:30 | J16: 15千克 | K16: 0.5元/千克 | L16: 100 | M16: 30 | N16: 最近两个连续月份合约，其后月份在标的期货合约结算后持仓量达到一定数值之后的第二个交易日挂牌。合约月份涉及的标的期货持仓量阈值为20000手（单边） | S16: 44921 | T16: √ | U16: 2025.03.04
C17: 合成橡胶期权 | D17: br_o | E17: 合成橡胶期货合约 | F17: 21:00-23:00 | J17: 5吨 | K17: 1元/吨 | L17: 100 | M17: 30 | N17: 最近两个连续月份合约，其后月份在标的期货合约结算后持仓量达到一定数值之后的第二个交易日挂牌。合约月份涉及的标的期货持仓量阈值为10000手（单边） | S17: 45138 | U17: ——
C18: 铅期权 | D18: pb_o | E18: 铅期货合约 | F18: 21:00-01:00 | J18: 5吨 | K18: 1元/吨 | L18: 100 | M18: 30 | N18: 最近两个连续月份合约，其后月份在标的期货合约结算后持仓量达到一定数值之后的第二个交易日挂牌。合约月份涉及的标的期货持仓量阈值均为10000手（单边） | S18: 45537 | T18: √ | U18: 2025.06.20
C19: 镍期权 | D19: ni_o | E19: 镍期货合约 | F19: 21:00-01:00 | J19: 1吨 | K19: 2元/吨 | L19: 100 | M19: 30 | N19: 最近两个连续月份合约，其后月份在标的期货合约结算后持仓量达到一定数值之后的第二个交易日挂牌。合约月份涉及的标的期货持仓量阈值均为10000手（单边） | S19: 45537 | T19: √ | U19: 2026.04.22 | V19: √
C20: 锡期权 | D20: sn_o | E20: 锡期货合约 | F20: 21:00-01:00 | J20: 1吨 | K20: 2元/吨 | L20: 100 | M20: 30 | N20: 最近两个连续月份合约，其后月份在标的期货合约结算后持仓量达到一定数值之后的第二个交易日挂牌。合约月份涉及的标的期货持仓量阈值均为10000手（单边） | S20: 45537 | T20: √ | U20: 2025.06.20
C21: 氧化铝期权 | D21: ao_o | E21: 氧化铝期货合约 | F21: 21:00-01:00 | J21: 20吨 | K21: 0.5元/吨 | L21: 100 | M21: 30 | N21: 最近两个连续月份合约，其后月份在标的期货合约结算后持仓量达到一定数值之后的第二个交易日挂牌。合约月份涉及的标的期货持仓量阈值均为10000手（单边） | S21: 45537 | U21: ——
C22: 铸造铝合金期权 | D22: ad_o | E22: 铸造铝合金期货合约 | F22: 21:00-01:00 | J22: 10吨 | K22: 1元/吨 | L22: 100 | M22: 30 | N22: 最近两个连续月份合约，其后月份在标的期货合约结算后持仓量达到一定数值之后的第二个交易日挂牌。合约月份涉及的标的期货持仓量阈值均为10000手（单边） | S22: 45819 | U22: ——
C23: 石油沥青期权 | D23: bu_o | E23: 石油沥青期货合约 | F23: 21:00-23:00 | J23: 10吨 | K23: 0.5元/吨 | L23: 100 | M23: 30 | N23: 最近两个连续月份合约，其后月份在标的期货合约结算后持仓量达到一定数值之后的第二个交易日挂牌。合约月份涉及的标的期货持仓量阈值均为50000手（单边） | S23: 45910 | T23: √ | U23: 2025.09.10
C24: 纸浆期权 | D24: sp_o | E24: 纸浆期货合约 | F24: 21:00-23:00 | J24: 10吨 | K24: 1元/吨 | L24: 100 | M24: 30 | N24: 最近两个连续月份合约，其后月份在标的期货合约结算后持仓量达到一定数值之后的第二个交易日挂牌。合约月份涉及的标的期货持仓量阈值均为20000手（单边） | S24: 45910 | T24: √ | U24: 2025.09.10
C25: 胶版印刷纸期权 | D25: op_o | E25: 胶版印刷纸期货合约 | F25: 21:00-23:00 | J25: 40吨 | K25: 1元/吨 | L25: 100 | M25: 30 | N25: 最近两个连续月份合约，其后月份在标的期货合约结算后持仓量达到一定数值之后的第二个交易日挂牌。合约月份涉及的标的期货持仓量阈值均为5000手（单边） | S25: 45910 | U25: ——
C26: 燃料油期权 | D26: fu_o | E26: 燃料油期货合约 | F26: 21:00-23:00 | J26: 10吨 | K26: 0.5元/吨 | L26: 100 | M26: 30 | N26: 最近两个连续月份合约，其后月份在标的期货合约结算后持仓量达到一定数值之后的第二个交易日挂牌。合约月份涉及的标的期货持仓量阈值均为30000手（单边） | O26: 标的期货合约交割月份前一个月的倒数第十个交易日 | S26: 45910 | T26: √ | U26: 2025.09.10
B27: 大商所 | C27: 豆粕期权 | D27: 常规期权：m_o 系列期权： m_MS_o | E27: 豆粕期货合约 | F27: 21:00-23:00 | G27: 期权卖方交易保证金中涉及标的期货合约的公司交易保证金收取标准为同期货保证金率 | H27: 期权合约结算价×标的期货合约交易单位+MAX[标的期货合约交易所保证金－（1/2）×期权虚值额，（1/2）×标的期货合约交易所保证金] | I27: 与期货合约涨跌停板幅度相同 | J27: 10 吨 | K27: 0.5元/吨 | L27: 1000 | M27: 无市价 | N27: 1、3、5、7、8、9、11、12月 | O27: 常规期权：标的期货合约交割月份前一个月的第12个交易日； 系列期权：标的期货合约交割月份前两个月的第12个交易日 | P27: 同最后交易日 | Q27: 美式 | R27: 实物 | S27: 常规期权：2017/3/31 系列期权： 2026/2/2 | T27: √ | U27: 2022.09.05 | V27: √
C28: 玉米期权 | D28: 常规期权：c_o 系列期权：c_MS_o | E28: 玉米期货合约 | F28: 21:00-23:00 | J28: 10 吨 | K28: 0.5元/吨 | L28: 2000 | M28: 无市价 | N28: 1、3、5、7、9、11月 | S28: 常规期权：2019/1/28 系列期权： 2026/2/2 | U28: ——
C29: 铁矿石期权 | D29: i_o | E29: 铁矿石期货合约 | F29: 21:00-23:00 | J29: 100吨 | K29: 0.1元/吨 | L29: 1000 | M29: 无市价 | N29: 1-12月 | O29: 标的期货合约交割月份前一个月的第12个交易日 | S29: 43808 | T29: √ | U29: 2022.09.05
C30: 液化石油气期权 | D30: pg_o | E30: 液化石油气期货合约 | F30: 21:00-23:00 | J30: 20吨 | K30: 0.2元/吨 | L30: 1000 | M30: 无市价 | N30: 1-12月 | S30: 43920 | T30: √ | U30: 2025.06.20
C31: 聚丙烯期权 | D31: pp_o | E31: 聚丙烯期货合约 | F31: 21:00-23:00 | J31: 5吨 | K31: 0.5元/吨 | L31: 1000 | M31: 无市价 | N31: 1-12月 | S31: 44018 | T31: √ | U31: 2025.03.04
C32: 聚氯乙烯期权 | D32: v_o | E32: 聚氯乙烯期货合约 | F32: 21:00-23:00 | J32: 5吨 | K32: 0.5元/吨 | L32: 1000 | M32: 无市价 | N32: 1-12月 | S32: 44018 | T32: √ | U32: 2025.03.04
C33: 聚乙烯期权 | D33: l_o | E33: 聚乙烯期货合约 | F33: 21:00-23:00 | J33: 5吨 | K33: 0.5元/吨 | L33: 1000 | M33: 无市价 | N33: 1-12月 | S33: 44018 | T33: √ | U33: 2022.09.05
C34: 棕榈油期权 | D34: p_o | E34: 棕榈油期货合约 | F34: 21:00-23:00 | J34: 10吨 | K34: 0.5元/吨 | L34: 1000 | M34: 无市价 | N34: 1-12月 | S34: 44365 | T34: √ | U34: 2022.09.05 | V34: √
C35: 黄大豆1号期权 | D35: 常规期权：a_o 系列期权：a_MS_o | E35: 黄大豆1号期货合约 | F35: 21:00-23:00 | J35: 10吨 | K35: 0.5元/吨 | L35: 1000 | M35: 无市价 | N35: 1、3、5、7、9、11 月 | O35: 常规期权：标的期货合约交割月份前一个月的第12个交易日； 系列期权：标的期货合约交割月份前两个月的第12个交易日。 | S35: 44781 | T35: √ | U35: 2022.09.05 | V35: √
C36: 黄大豆2号期权 | D36: b_o | E36: 黄大豆2号期货合约 | F36: 21:00-23:00 | J36: 10吨 | K36: 0.5元/吨 | L36: 1000 | M36: 无市价 | N36: 1-12月 | O36: 标的期货合约交割月份前一个月的第12个交易日 | S36: 44781 | T36: √ | U36: 2022.09.05 | V36: √
C37: 豆油期权 | D37: 常规期权：y_o 系列期权：y_MS_o | E37: 豆油期货合约 | F37: 21:00-23:00 | J37: 10吨 | K37: 0.5元/吨 | L37: 1000 | M37: 无市价 | N37: 常规期权：1、3、5、7、8、9、11、12月 系列期权：3、5、7、11月 | O37: 常规期权：标的期货合约交割月份前一个月的第12个交易日； 系列期权：标的期货合约交割月份前两个月的第12个交易日 | S37: 44781 | T37: √ | U37: 2022.09.05 | V37: √
C38: 乙二醇期权 | D38: eg_o | E38: 乙二醇期货合约 | F38: 21:00-23:00 | J38: 10吨 | K38: 0.5元/吨 | L38: 1000 | M38: 无市价 | N38: 1-12月 | O38: 标的期货合约交割月份前一个月的第12个交易日 | S38: 45061 | T38: √ | U38: 2025.06.20
C39: 苯乙烯期权 | D39: eb_o | E39: 苯乙烯期货合约 | F39: 21:00-23:00 | J39: 5吨 | K39: 0.5元/吨 | L39: 1000 | M39: 无市价 | N39: 1-12月 | S39: 45061 | T39: √ | U39: 2025.03.04
C40: 鸡蛋期权 | D40: jd_o | E40: 鸡蛋期货合约 | F40: 无 | J40: 5吨 | K40: 0.5元/500千克 | L40: 300 | M40: 无市价 | N40: 1-12月 | S40: 45527 | U40: ——
...

Sheet 保证金及涨跌停板幅度表
A1: 点此返回目录
B2: 期货品种保证金标准及涨跌停板幅度表
B3: 交易所 | C3: 品种名称 | D3: 品种代码 | E3: 合约单位 | F3: 公司加收 | G3: 按连续单边市调整的交易所保证金率 | M3: 连续单边市涨跌停板 | P3: 按时间梯度调整的交易所保证金率 | V3: QFII&RQFII | W3: 国际化品种
G4: 投机 | J4: 套保 | P4: 交割月前1个月 | R4: 交割月份
G5: 一般月份 | H5: 第一个单边市结算时 | I5: 第二个同方向单边市结算时 | J5: 一般月份 | K5: 第一个单边市结算时 | L5: 第二个同方向单边市结算时 | M5: 一般月份 | N5: 第一个单边市结算后 | O5: 第二个同方向单边市结算后 | P5: 第1个交易日起 （投机） | Q5: 第1个交易日起 （套保） | R5: 第1个交易日起 （投机） | S5: 第1个交易日起 （套保） | T5: 最后交易日前2个交易日起 （投机） | U5: 最后交易日前2个交易日起 （套保）
B6: 上海期货交易所 | C6: 螺纹钢 | D6: rb | E6: 10吨 | F6: 0.06 | G6: 0.07 | H6: =MAX(G6,N6+2%) -> 0.1 | I6: =MAX(G6,O6+2%) -> 0.12 | J6: 0.06 | K6: =MAX(J6,N6+2%) -> 0.1 | L6: =MAX(J6,O6+2%) -> 0.12 | M6: 0.05 | N6: =M6+3% -> 0.08 | O6: =N6+2% -> 0.1 | P6: =MAX(10%,G6) -> 0.1 | Q6: =MAX(10%,J6) -> 0.1 | R6: =MAX(15%,G6) -> 0.15 | S6: =MAX(15%,J6) -> 0.15 | T6: =MAX(20%,G6) -> 0.2 | U6: =MAX(J6,20%) -> 0.2 | V6: =IFERROR(IF(VLOOKUP(D6,期货合约要素!$D:$Q,12,0)=0,"",VLOOKUP(D6,期货合约要素!$D:$Q,12,0)),IF(VLOOKUP(D6,期权合约要素!$D:$V,17,0)=0,"",VLOOKUP(D6,期权合约要素!$D:$V,17,0))) -> √ | W6: =IFERROR(IF(VLOOKUP(D6,期货合约要素!$D:$Q,14,0)=0,"",VLOOKUP(D6,期货合约要素!$D:$Q,14,0)),IF(VLOOKUP(D6,期权合约要素!$D:$V,19,0)=0,"",VLOOKUP(D6,期权合约要素!$D:$V,19,0)))
C7: 热轧卷板 | D7: hc | E7: 10吨 | F7: 0.06 | G7: 0.07 | H7: =MAX(G7,N7+2%) -> 0.1 | I7: =MAX(G7,O7+2%) -> 0.12 | J7: 0.06 | K7: =MAX(J7,N7+2%) -> 0.1 | L7: =MAX(J7,O7+2%) -> 0.12 | M7: 0.05 | N7: =M7+3% -> 0.08 | O7: =N7+2% -> 0.1 | P7: =MAX(10%,G7) -> 0.1 | Q7: =MAX(10%,J7) -> 0.1 | R7: =MAX(15%,G7) -> 0.15 | S7: =MAX(15%,J7) -> 0.15 | T7: =MAX(20%,G7) -> 0.2 | U7: =MAX(J7,20%) -> 0.2 | V7: =IFERROR(IF(VLOOKUP(D7,期货合约要素!$D:$Q,12,0)=0,"",VLOOKUP(D7,期货合约要素!$D:$Q,12,0)),IF(VLOOKUP(D7,期权合约要素!$D:$V,17,0)=0,"",VLOOKUP(D7,期权合约要素!$D:$V,17,0))) -> √ | W7: =IFERROR(IF(VLOOKUP(D7,期货合约要素!$D:$Q,14,0)=0,"",VLOOKUP(D7,期货合约要素!$D:$Q,14,0)),IF(VLOOKUP(D7,期权合约要素!$D:$V,19,0)=0,"",VLOOKUP(D7,期权合约要素!$D:$V,19,0)))
C8: 线材 | D8: wr | E8: 10吨 | F8: 0.06 | G8: 0.09 | H8: =MAX(G8,N8+2%) -> 0.12 | I8: =MAX(G8,O8+2%) -> 0.14 | J8: 0.08 | K8: =MAX(J8,N8+2%) -> 0.12 | L8: =MAX(J8,O8+2%) -> 0.14 | M8: 0.07 | N8: =M8+3% -> 0.1 | O8: =N8+2% -> 0.12 | P8: =MAX(10%,G8) -> 0.1 | Q8: =MAX(10%,J8) -> 0.1 | R8: =MAX(15%,G8) -> 0.15 | S8: =MAX(15%,J8) -> 0.15 | T8: =MAX(20%,G8) -> 0.2 | U8: =MAX(J8,20%) -> 0.2 | V8: =IFERROR(IF(VLOOKUP(D8,期货合约要素!$D:$Q,12,0)=0,"",VLOOKUP(D8,期货合约要素!$D:$Q,12,0)),IF(VLOOKUP(D8,期权合约要素!$D:$V,17,0)=0,"",VLOOKUP(D8,期权合约要素!$D:$V,17,0))) | W8: =IFERROR(IF(VLOOKUP(D8,期货合约要素!$D:$Q,14,0)=0,"",VLOOKUP(D8,期货合约要素!$D:$Q,14,0)),IF(VLOOKUP(D8,期权合约要素!$D:$V,19,0)=0,"",VLOOKUP(D8,期权合约要素!$D:$V,19,0)))
C9: 线材 wr2607-wr2702合约 | G9: 0.1 | H9: =MAX(G9,N9+2%) -> 0.13 | I9: =MAX(G9,O9+2%) -> 0.15 | J9: 0.09 | K9: =MAX(J9,N9+2%) -> 0.13 | L9: =MAX(J9,O9+2%) -> 0.15 | M9: 0.08 | N9: =M9+3% -> 0.11 | O9: =N9+2% -> 0.13 | P9: =MAX(10%,G9) -> 0.1 | Q9: =MAX(10%,J9) -> 0.1 | R9: =MAX(15%,G9) -> 0.15 | S9: =MAX(15%,J9) -> 0.15 | T9: =MAX(20%,G9) -> 0.2 | U9: =MAX(J9,20%) -> 0.2
C10: 铜 | D10: cu | E10: 5吨 | F10: 0.07 | G10: 0.09 | H10: =MAX(G10,N10+2%) -> 0.12 | I10: =MAX(G10,O10+2%) -> 0.14 | J10: 0.08 | K10: =MAX(J10,N10+2%) -> 0.12 | L10: =MAX(J10,O10+2%) -> 0.14 | M10: 0.07 | N10: =M10+3% -> 0.1 | O10: =N10+2% -> 0.12 | P10: =MAX(10%,G10) -> 0.1 | Q10: =MAX(10%,J10) -> 0.1 | R10: =MAX(15%,G10) -> 0.15 | S10: =MAX(15%,J10) -> 0.15 | T10: =MAX(20%,G10) -> 0.2 | U10: =MAX(J10,20%) -> 0.2 | V10: =IFERROR(IF(VLOOKUP(D10,期货合约要素!$D:$Q,12,0)=0,"",VLOOKUP(D10,期货合约要素!$D:$Q,12,0)),IF(VLOOKUP(D10,期权合约要素!$D:$V,17,0)=0,"",VLOOKUP(D10,期权合约要素!$D:$V,17,0))) -> √ | W10: =IFERROR(IF(VLOOKUP(D10,期货合约要素!$D:$Q,14,0)=0,"",VLOOKUP(D10,期货合约要素!$D:$Q,14,0)),IF(VLOOKUP(D10,期权合约要素!$D:$V,19,0)=0,"",VLOOKUP(D10,期权合约要素!$D:$V,19,0)))
C11: 铜 cu2607-cu2702合约 | G11: 0.11 | H11: =MAX(G11,N11+2%) -> 0.14 | I11: =MAX(G11,O11+2%) -> 0.16 | J11: 0.1 | K11: =MAX(J11,N11+2%) -> 0.14 | L11: =MAX(J11,O11+2%) -> 0.16 | M11: 0.09 | N11: =M11+3% -> 0.12 | O11: =N11+2% -> 0.14 | P11: =MAX(10%,G11) -> 0.11 | Q11: =MAX(10%,J11) -> 0.1 | R11: =MAX(15%,G11) -> 0.15 | S11: =MAX(15%,J11) -> 0.15 | T11: =MAX(20%,G11) -> 0.2 | U11: =MAX(J11,20%) -> 0.2
C12: 铝 | D12: al | E12: 5吨 | F12: 0.07 | G12: 0.09 | H12: =MAX(G12,N12+2%) -> 0.12 | I12: =MAX(G12,O12+2%) -> 0.14 | J12: 0.08 | K12: =MAX(J12,N12+2%) -> 0.12 | L12: =MAX(J12,O12+2%) -> 0.14 | M12: 0.07 | N12: =M12+3% -> 0.1 | O12: =N12+2% -> 0.12 | P12: =MAX(10%,G12) -> 0.1 | Q12: =MAX(10%,J12) -> 0.1 | R12: =MAX(15%,G12) -> 0.15 | S12: =MAX(15%,J12) -> 0.15 | T12: =MAX(20%,G12) -> 0.2 | U12: =MAX(J12,20%) -> 0.2 | V12: =IFERROR(IF(VLOOKUP(D12,期货合约要素!$D:$Q,12,0)=0,"",VLOOKUP(D12,期货合约要素!$D:$Q,12,0)),IF(VLOOKUP(D12,期权合约要素!$D:$V,17,0)=0,"",VLOOKUP(D12,期权合约要素!$D:$V,17,0))) -> √ | W12: =IFERROR(IF(VLOOKUP(D12,期货合约要素!$D:$Q,14,0)=0,"",VLOOKUP(D12,期货合约要素!$D:$Q,14,0)),IF(VLOOKUP(D12,期权合约要素!$D:$V,19,0)=0,"",VLOOKUP(D12,期权合约要素!$D:$V,19,0)))
C13: 铝 al2607-al2702合约 | G13: 0.11 | H13: =MAX(G13,N13+2%) -> 0.14 | I13: =MAX(G13,O13+2%) -> 0.16 | J13: 0.1 | K13: =MAX(J13,N13+2%) -> 0.14 | L13: =MAX(J13,O13+2%) -> 0.16 | M13: 0.09 | N13: =M13+3% -> 0.12 | O13: =N13+2% -> 0.14 | P13: =MAX(10%,G13) -> 0.11 | Q13: =MAX(10%,J13) -> 0.1 | R13: =MAX(15%,G13) -> 0.15 | S13: =MAX(15%,J13) -> 0.15 | T13: =MAX(20%,G13) -> 0.2 | U13: =MAX(J13,20%) -> 0.2
C14: 锌 | D14: zn | E14: 5吨 | F14: 0.07 | G14: 0.09 | H14: =MAX(G14,N14+2%) -> 0.12 | I14: =MAX(G14,O14+2%) -> 0.14 | J14: 0.08 | K14: =MAX(J14,N14+2%) -> 0.12 | L14: =MAX(J14,O14+2%) -> 0.14 | M14: 0.07 | N14: =M14+3% -> 0.1 | O14: =N14+2% -> 0.12 | P14: =MAX(10%,G14) -> 0.1 | Q14: =MAX(10%,J14) -> 0.1 | R14: =MAX(15%,G14) -> 0.15 | S14: =MAX(15%,J14) -> 0.15 | T14: =MAX(20%,G14) -> 0.2 | U14: =MAX(J14,20%) -> 0.2 | V14: =IFERROR(IF(VLOOKUP(D14,期货合约要素!$D:$Q,12,0)=0,"",VLOOKUP(D14,期货合约要素!$D:$Q,12,0)),IF(VLOOKUP(D14,期权合约要素!$D:$V,17,0)=0,"",VLOOKUP(D14,期权合约要素!$D:$V,17,0))) -> √ | W14: =IFERROR(IF(VLOOKUP(D14,期货合约要素!$D:$Q,14,0)=0,"",VLOOKUP(D14,期货合约要素!$D:$Q,14,0)),IF(VLOOKUP(D14,期权合约要素!$D:$V,19,0)=0,"",VLOOKUP(D14,期权合约要素!$D:$V,19,0)))
C15: 锌 zn2607-zn2702合约 | G15: 0.11 | H15: =MAX(G15,N15+2%) -> 0.14 | I15: =MAX(G15,O15+2%) -> 0.16 | J15: 0.1 | K15: =MAX(J15,N15+2%) -> 0.14 | L15: =MAX(J15,O15+2%) -> 0.16 | M15: 0.09 | N15: =M15+3% -> 0.12 | O15: =N15+2% -> 0.14 | P15: =MAX(10%,G15) -> 0.11 | Q15: =MAX(10%,J15) -> 0.1 | R15: =MAX(15%,G15) -> 0.15 | S15: =MAX(15%,J15) -> 0.15 | T15: =MAX(20%,G15) -> 0.2 | U15: =MAX(J15,20%) -> 0.2
C16: 铅 | D16: pb | E16: 5吨 | F16: 0.07 | G16: 0.09 | H16: =MAX(G16,N16+2%) -> 0.12 | I16: =MAX(G16,O16+2%) -> 0.14 | J16: 0.08 | K16: =MAX(J16,N16+2%) -> 0.12 | L16: =MAX(J16,O16+2%) -> 0.14 | M16: 0.07 | N16: =M16+3% -> 0.1 | O16: =N16+2% -> 0.12 | P16: =MAX(10%,G16) -> 0.1 | Q16: =MAX(10%,J16) -> 0.1 | R16: =MAX(15%,G16) -> 0.15 | S16: =MAX(15%,J16) -> 0.15 | T16: =MAX(20%,G16) -> 0.2 | U16: =MAX(J16,20%) -> 0.2 | V16: =IFERROR(IF(VLOOKUP(D16,期货合约要素!$D:$Q,12,0)=0,"",VLOOKUP(D16,期货合约要素!$D:$Q,12,0)),IF(VLOOKUP(D16,期权合约要素!$D:$V,17,0)=0,"",VLOOKUP(D16,期权合约要素!$D:$V,17,0))) -> √ | W16: =IFERROR(IF(VLOOKUP(D16,期货合约要素!$D:$Q,14,0)=0,"",VLOOKUP(D16,期货合约要素!$D:$Q,14,0)),IF(VLOOKUP(D16,期权合约要素!$D:$V,19,0)=0,"",VLOOKUP(D16,期权合约要素!$D:$V,19,0)))
C17: 铅 pb2607-pb2702合约 | G17: 0.11 | H17: =MAX(G17,N17+2%) -> 0.14 | I17: =MAX(G17,O17+2%) -> 0.16 | J17: 0.1 | K17: =MAX(J17,N17+2%) -> 0.14 | L17: =MAX(J17,O17+2%) -> 0.16 | M17: 0.09 | N17: =M17+3% -> 0.12 | O17: =N17+2% -> 0.14 | P17: =MAX(10%,G17) -> 0.11 | Q17: =MAX(10%,J17) -> 0.1 | R17: =MAX(15%,G17) -> 0.15 | S17: =MAX(15%,J17) -> 0.15 | T17: =MAX(20%,G17) -> 0.2 | U17: =MAX(J17,20%) -> 0.2
C18: 氧化铝 | D18: ao | E18: 20吨 | F18: 0.07 | G18: 0.09 | H18: =MAX(G18,N18+2%) -> 0.12 | I18: =MAX(G18,O18+2%) -> 0.14 | J18: 0.08 | K18: =MAX(J18,N18+2%) -> 0.12 | L18: =MAX(J18,O18+2%) -> 0.14 | M18: 0.07 | N18: =M18+3% -> 0.1 | O18: =N18+2% -> 0.12 | P18: =MAX(10%,G18) -> 0.1 | Q18: =MAX(10%,J18) -> 0.1 | R18: =MAX(15%,G18) -> 0.15 | S18: =MAX(15%,J18) -> 0.15 | T18: =MAX(20%,G18) -> 0.2 | U18: =MAX(J18,20%) -> 0.2 | V18: =IFERROR(IF(VLOOKUP(D18,期货合约要素!$D:$Q,12,0)=0,"",VLOOKUP(D18,期货合约要素!$D:$Q,12,0)),IF(VLOOKUP(D18,期权合约要素!$D:$V,17,0)=0,"",VLOOKUP(D18,期权合约要素!$D:$V,17,0))) | W18: =IFERROR(IF(VLOOKUP(D18,期货合约要素!$D:$Q,14,0)=0,"",VLOOKUP(D18,期货合约要素!$D:$Q,14,0)),IF(VLOOKUP(D18,期权合约要素!$D:$V,19,0)=0,"",VLOOKUP(D18,期权合约要素!$D:$V,19,0)))
C19: 氧化铝 ao2607-ao2702合约 | G19: 0.11 | H19: =MAX(G19,N19+2%) -> 0.14 | I19: =MAX(G19,O19+2%) -> 0.16 | J19: 0.1 | K19: =MAX(J19,N19+2%) -> 0.14 | L19: =MAX(J19,O19+2%) -> 0.16 | M19: 0.09 | N19: =M19+3% -> 0.12 | O19: =N19+2% -> 0.14 | P19: =MAX(10%,G19) -> 0.11 | Q19: =MAX(10%,J19) -> 0.1 | R19: =MAX(15%,G19) -> 0.15 | S19: =MAX(15%,J19) -> 0.15 | T19: =MAX(20%,G19) -> 0.2 | U19: =MAX(J19,20%) -> 0.2
C20: 不锈钢 | D20: ss | E20: 5吨 | F20: 0.06 | G20: 0.07 | H20: =MAX(G20,N20+2%) -> 0.1 | I20: =MAX(G20,O20+2%) -> 0.12 | J20: 0.06 | K20: =MAX(J20,N20+2%) -> 0.1 | L20: =MAX(J20,O20+2%) -> 0.12 | M20: 0.05 | N20: =M20+3% -> 0.08 | O20: =N20+2% -> 0.1 | P20: =MAX(10%,G20) -> 0.1 | Q20: =MAX(10%,J20) -> 0.1 | R20: =MAX(15%,G20) -> 0.15 | S20: =MAX(15%,J20) -> 0.15 | T20: =MAX(20%,G20) -> 0.2 | U20: =MAX(J20,20%) -> 0.2 | V20: =IFERROR(IF(VLOOKUP(D20,期货合约要素!$D:$Q,12,0)=0,"",VLOOKUP(D20,期货合约要素!$D:$Q,12,0)),IF(VLOOKUP(D20,期权合约要素!$D:$V,17,0)=0,"",VLOOKUP(D20,期权合约要素!$D:$V,17,0))) -> √ | W20: =IFERROR(IF(VLOOKUP(D20,期货合约要素!$D:$Q,14,0)=0,"",VLOOKUP(D20,期货合约要素!$D:$Q,14,0)),IF(VLOOKUP(D20,期权合约要素!$D:$V,19,0)=0,"",VLOOKUP(D20,期权合约要素!$D:$V,19,0)))
C21: 镍 | D21: ni | E21: 1吨 | F21: 0.08 | G21: 0.1 | H21: =MAX(G21,N21+2%) -> 0.13 | I21: =MAX(G21,O21+2%) -> 0.15 | J21: 0.09 | K21: =MAX(J21,N21+2%) -> 0.13 | L21: =MAX(J21,O21+2%) -> 0.15 | M21: 0.08 | N21: =M21+3% -> 0.11 | O21: =N21+2% -> 0.13 | P21: =MAX(10%,G21) -> 0.1 | Q21: =MAX(10%,J21) -> 0.1 | R21: =MAX(15%,G21) -> 0.15 | S21: =MAX(15%,J21) -> 0.15 | T21: =MAX(20%,G21) -> 0.2 | U21: =MAX(J21,20%) -> 0.2 | V21: =IFERROR(IF(VLOOKUP(D21,期货合约要素!$D:$Q,12,0)=0,"",VLOOKUP(D21,期货合约要素!$D:$Q,12,0)),IF(VLOOKUP(D21,期权合约要素!$D:$V,17,0)=0,"",VLOOKUP(D21,期权合约要素!$D:$V,17,0))) -> √ | W21: =IFERROR(IF(VLOOKUP(D21,期货合约要素!$D:$Q,14,0)=0,"",VLOOKUP(D21,期货合约要素!$D:$Q,14,0)),IF(VLOOKUP(D21,期权合约要素!$D:$V,19,0)=0,"",VLOOKUP(D21,期权合约要素!$D:$V,19,0))) -> √
C22: 镍 ni2607-ni2703合约 | G22: 0.12 | H22: =MAX(G22,N22+2%) -> 0.15 | I22: =MAX(G22,O22+2%) -> 0.17 | J22: 0.11 | K22: =MAX(J22,N22+2%) -> 0.15 | L22: =MAX(J22,O22+2%) -> 0.17 | M22: 0.1 | N22: =M22+3% -> 0.13 | O22: =N22+2% -> 0.15 | P22: =MAX(10%,G22) -> 0.12 | Q22: =MAX(10%,J22) -> 0.11 | R22: =MAX(15%,G22) -> 0.15 | S22: =MAX(15%,J22) -> 0.15 | T22: =MAX(20%,G22) -> 0.2 | U22: =MAX(J22,20%) -> 0.2
C23: 锡 | D23: sn | E23: 1吨 | F23: 0.1 | G23: 0.13 | H23: =MAX(G23,N23+2%) -> 0.16 | I23: =MAX(G23,O23+2%) -> 0.18 | J23: 0.12 | K23: =MAX(J23,N23+2%) -> 0.16 | L23: =MAX(J23,O23+2%) -> 0.18 | M23: 0.11 | N23: =M23+3% -> 0.14 | O23: =N23+2% -> 0.16 | P23: =MAX(10%,G23) -> 0.13 | Q23: =MAX(10%,J23) -> 0.12 | R23: =MAX(15%,G23) -> 0.15 | S23: =MAX(15%,J23) -> 0.15 | T23: =MAX(20%,G23) -> 0.2 | U23: =MAX(J23,20%) -> 0.2 | V23: =IFERROR(IF(VLOOKUP(D23,期货合约要素!$D:$Q,12,0)=0,"",VLOOKUP(D23,期货合约要素!$D:$Q,12,0)),IF(VLOOKUP(D23,期权合约要素!$D:$V,17,0)=0,"",VLOOKUP(D23,期权合约要素!$D:$V,17,0))) -> √ | W23: =IFERROR(IF(VLOOKUP(D23,期货合约要素!$D:$Q,14,0)=0,"",VLOOKUP(D23,期货合约要素!$D:$Q,14,0)),IF(VLOOKUP(D23,期权合约要素!$D:$V,19,0)=0,"",VLOOKUP(D23,期权合约要素!$D:$V,19,0)))
C24: 锡 sn2607-sn2703合约 | G24: 0.14 | H24: =MAX(G24,N24+2%) -> 0.17 | I24: =MAX(G24,O24+2%) -> 0.19 | J24: 0.13 | K24: =MAX(J24,N24+2%) -> 0.17 | L24: =MAX(J24,O24+2%) -> 0.19 | M24: 0.12 | N24: =M24+3% -> 0.15 | O24: =N24+2% -> 0.17 | P24: =MAX(10%,G24) -> 0.14 | Q24: =MAX(10%,J24) -> 0.13 | R24: =MAX(15%,G24) -> 0.15 | S24: =MAX(15%,J24) -> 0.15 | T24: =MAX(20%,G24) -> 0.2 | U24: =MAX(J24,20%) -> 0.2
C25: 黄金 | D25: au | E25: 1000克 | F25: 0.12 | G25: 0.16 | H25: =MAX(G25,N25+2%) -> 0.19 | I25: =MAX(G25,O25+2%) -> 0.21 | J25: 0.15 | K25: =MAX(J25,N25+2%) -> 0.19 | L25: =MAX(J25,O25+2%) -> 0.21 | M25: 0.14 | N25: =M25+3% -> 0.17 | O25: =N25+2% -> 0.19 | P25: =MAX(10%,G25) -> 0.16 | Q25: =MAX(10%,J25) -> 0.15 | R25: =MAX(15%,G25) -> 0.16 | S25: =MAX(15%,J25) -> 0.15 | T25: =MAX(20%,G25) -> 0.2 | U25: =MAX(J25,20%) -> 0.2 | V25: =IFERROR(IF(VLOOKUP(D25,期货合约要素!$D:$Q,12,0)=0,"",VLOOKUP(D25,期货合约要素!$D:$Q,12,0)),IF(VLOOKUP(D25,期权合约要素!$D:$V,17,0)=0,"",VLOOKUP(D25,期权合约要素!$D:$V,17,0))) -> √ | W25: =IFERROR(IF(VLOOKUP(D25,期货合约要素!$D:$Q,14,0)=0,"",VLOOKUP(D25,期货合约要素!$D:$Q,14,0)),IF(VLOOKUP(D25,期权合约要素!$D:$V,19,0)=0,"",VLOOKUP(D25,期权合约要素!$D:$V,19,0)))
C26: 白银 | D26: ag | E26: 15千克 | F26: 0.16 | G26: 0.16 | H26: =MAX(G26,N26+2%) -> 0.19 | I26: =MAX(G26,O26+2%) -> 0.21 | J26: 0.15 | K26: =MAX(J26,N26+2%) -> 0.19 | L26: =MAX(J26,O26+2%) -> 0.21 | M26: 0.14 | N26: =M26+3% -> 0.17 | O26: =N26+2% -> 0.19 | P26: =MAX(10%,G26) -> 0.16 | Q26: =MAX(10%,J26) -> 0.15 | R26: =MAX(15%,G26) -> 0.16 | S26: =MAX(15%,J26) -> 0.15 | T26: =MAX(20%,G26) -> 0.2 | U26: =MAX(J26,20%) -> 0.2 | V26: =IFERROR(IF(VLOOKUP(D26,期货合约要素!$D:$Q,12,0)=0,"",VLOOKUP(D26,期货合约要素!$D:$Q,12,0)),IF(VLOOKUP(D26,期权合约要素!$D:$V,17,0)=0,"",VLOOKUP(D26,期权合约要素!$D:$V,17,0))) -> √ | W26: =IFERROR(IF(VLOOKUP(D26,期货合约要素!$D:$Q,14,0)=0,"",VLOOKUP(D26,期货合约要素!$D:$Q,14,0)),IF(VLOOKUP(D26,期权合约要素!$D:$V,19,0)=0,"",VLOOKUP(D26,期权合约要素!$D:$V,19,0)))
C27: 白银 ag2607-ag2704合约 | G27: 0.22 | H27: =MAX(G27,N27+2%) -> 0.25 | I27: =MAX(G27,O27+2%) -> 0.27 | J27: 0.21 | K27: =MAX(J27,N27+2%) -> 0.25 | L27: =MAX(J27,O27+2%) -> 0.27 | M27: 0.2 | N27: =M27+3% -> 0.23 | O27: =N27+2% -> 0.25 | P27: =MAX(10%,G27) -> 0.22 | Q27: =MAX(10%,J27) -> 0.21 | R27: =MAX(15%,G27) -> 0.22 | S27: =MAX(15%,J27) -> 0.21 | T27: =MAX(20%,G27) -> 0.22 | U27: =MAX(J27,20%) -> 0.21
C28: 白银 ag2705-ag2706合约 | G28: 0.19 | H28: =MAX(G28,N28+2%) -> 0.22 | I28: =MAX(G28,O28+2%) -> 0.24 | J28: 0.18 | K28: =MAX(J28,N28+2%) -> 0.22 | L28: =MAX(J28,O28+2%) -> 0.24 | M28: 0.17 | N28: =M28+3% -> 0.2 | O28: =N28+2% -> 0.22 | P28: =MAX(10%,G28) -> 0.19 | Q28: =MAX(10%,J28) -> 0.18 | R28: =MAX(15%,G28) -> 0.19 | S28: =MAX(15%,J28) -> 0.18 | T28: =MAX(20%,G28) -> 0.2 | U28: =MAX(J28,20%) -> 0.2
C29: 天然橡胶 | D29: ru | E29: 10吨 | F29: 0.06 | G29: 0.09 | H29: =MAX(G29,N29+2%) -> 0.12 | I29: =MAX(G29,O29+2%) -> 0.14 | J29: 0.08 | K29: =MAX(J29,N29+2%) -> 0.12 | L29: =MAX(J29,O29+2%) -> 0.14 | M29: 0.07 | N29: =M29+3% -> 0.1 | O29: =N29+2% -> 0.12 | P29: =MAX(10%,G29) -> 0.1 | Q29: =MAX(10%,J29) -> 0.1 | R29: =MAX(15%,G29) -> 0.15 | S29: =MAX(15%,J29) -> 0.15 | T29: =MAX(20%,G29) -> 0.2 | U29: =MAX(J29,20%) -> 0.2 | V29: =IFERROR(IF(VLOOKUP(D29,期货合约要素!$D:$Q,12,0)=0,"",VLOOKUP(D29,期货合约要素!$D:$Q,12,0)),IF(VLOOKUP(D29,期权合约要素!$D:$V,17,0)=0,"",VLOOKUP(D29,期权合约要素!$D:$V,17,0))) -> √ | W29: =IFERROR(IF(VLOOKUP(D29,期货合约要素!$D:$Q,14,0)=0,"",VLOOKUP(D29,期货合约要素!$D:$Q,14,0)),IF(VLOOKUP(D29,期权合约要素!$D:$V,19,0)=0,"",VLOOKUP(D29,期权合约要素!$D:$V,19,0)))
C30: 石油沥青 | D30: bu | E30: 10吨 | F30: 0.1 | G30: 0.12 | H30: =MAX(G30,N30+2%) -> 0.15 | I30: =MAX(G30,O30+2%) -> 0.17 | J30: 0.11 | K30: =MAX(J30,N30+2%) -> 0.15 | L30: =MAX(J30,O30+2%) -> 0.17 | M30: 0.1 | N30: =M30+3% -> 0.13 | O30: =N30+2% -> 0.15 | P30: =MAX(10%,G30) -> 0.12 | Q30: =MAX(10%,J30) -> 0.11 | R30: =MAX(15%,G30) -> 0.15 | S30: =MAX(15%,J30) -> 0.15 | T30: =MAX(20%,G30) -> 0.2 | U30: =MAX(J30,20%) -> 0.2 | V30: =IFERROR(IF(VLOOKUP(D30,期货合约要素!$D:$Q,12,0)=0,"",VLOOKUP(D30,期货合约要素!$D:$Q,12,0)),IF(VLOOKUP(D30,期权合约要素!$D:$V,17,0)=0,"",VLOOKUP(D30,期权合约要素!$D:$V,17,0))) -> √ | W30: =IFERROR(IF(VLOOKUP(D30,期货合约要素!$D:$Q,14,0)=0,"",VLOOKUP(D30,期货合约要素!$D:$Q,14,0)),IF(VLOOKUP(D30,期权合约要素!$D:$V,19,0)=0,"",VLOOKUP(D30,期权合约要素!$D:$V,19,0)))
C31: 纸浆 | D31: sp | E31: 10吨 | F31: 0.06 | G31: 0.07 | H31: =MAX(G31,N31+2%) -> 0.1 | I31: =MAX(G31,O31+2%) -> 0.12 | J31: 0.06 | K31: =MAX(J31,N31+2%) -> 0.1 | L31: =MAX(J31,O31+2%) -> 0.12 | M31: 0.05 | N31: =M31+3% -> 0.08 | O31: =N31+2% -> 0.1 | P31: =MAX(10%,G31) -> 0.1 | Q31: =MAX(10%,J31) -> 0.1 | R31: =MAX(15%,G31) -> 0.15 | S31: =MAX(15%,J31) -> 0.15 | T31: =MAX(20%,G31) -> 0.2 | U31: =MAX(J31,20%) -> 0.2 | V31: =IFERROR(IF(VLOOKUP(D31,期货合约要素!$D:$Q,12,0)=0,"",VLOOKUP(D31,期货合约要素!$D:$Q,12,0)),IF(VLOOKUP(D31,期权合约要素!$D:$V,17,0)=0,"",VLOOKUP(D31,期权合约要素!$D:$V,17,0))) -> √ | W31: =IFERROR(IF(VLOOKUP(D31,期货合约要素!$D:$Q,14,0)=0,"",VLOOKUP(D31,期货合约要素!$D:$Q,14,0)),IF(VLOOKUP(D31,期权合约要素!$D:$V,19,0)=0,"",VLOOKUP(D31,期权合约要素!$D:$V,19,0)))
C32: 合成橡胶 | D32: br | E32: 5吨 | F32: 0.1 | G32: 0.12 | H32: =MAX(G32,N32+2%) -> 0.15 | I32: =MAX(G32,O32+2%) -> 0.17 | J32: 0.11 | K32: =MAX(J32,N32+2%) -> 0.15 | L32: =MAX(J32,O32+2%) -> 0.17 | M32: 0.1 | N32: =M32+3% -> 0.13 | O32: =N32+2% -> 0.15 | P32: =MAX(10%,G32) -> 0.12 | Q32: =MAX(10%,J32) -> 0.11 | R32: =MAX(15%,G32) -> 0.15 | S32: =MAX(15%,J32) -> 0.15 | T32: =MAX(20%,G32) -> 0.2 | U32: =MAX(J32,20%) -> 0.2 | V32: =IFERROR(IF(VLOOKUP(D32,期货合约要素!$D:$Q,12,0)=0,"",VLOOKUP(D32,期货合约要素!$D:$Q,12,0)),IF(VLOOKUP(D32,期权合约要素!$D:$V,17,0)=0,"",VLOOKUP(D32,期权合约要素!$D:$V,17,0))) | W32: =IFERROR(IF(VLOOKUP(D32,期货合约要素!$D:$Q,14,0)=0,"",VLOOKUP(D32,期货合约要素!$D:$Q,14,0)),IF(VLOOKUP(D32,期权合约要素!$D:$V,19,0)=0,"",VLOOKUP(D32,期权合约要素!$D:$V,19,0)))
C33: 铸造铝合金 | D33: ad | E33: 10吨 | F33: 0.07 | G33: 0.07 | H33: =MAX(G33,N33+2%) -> 0.1 | I33: =MAX(G33,O33+2%) -> 0.12 | J33: 0.06 | K33: =MAX(J33,N33+2%) -> 0.1 | L33: =MAX(J33,O33+2%) -> 0.12 | M33: 0.05 | N33: =M33+3% -> 0.08 | O33: =N33+2% -> 0.1 | P33: =MAX(10%,G33) -> 0.1 | Q33: =MAX(10%,J33) -> 0.1 | R33: =MAX(15%,G33) -> 0.15 | S33: =MAX(15%,J33) -> 0.15 | T33: =MAX(20%,G33) -> 0.2 | U33: =MAX(J33,20%) -> 0.2 | V33: =IFERROR(IF(VLOOKUP(D33,期货合约要素!$D:$Q,12,0)=0,"",VLOOKUP(D33,期货合约要素!$D:$Q,12,0)),IF(VLOOKUP(D33,期权合约要素!$D:$V,17,0)=0,"",VLOOKUP(D33,期权合约要素!$D:$V,17,0))) | W33: =IFERROR(IF(VLOOKUP(D33,期货合约要素!$D:$Q,14,0)=0,"",VLOOKUP(D33,期货合约要素!$D:$Q,14,0)),IF(VLOOKUP(D33,期权合约要素!$D:$V,19,0)=0,"",VLOOKUP(D33,期权合约要素!$D:$V,19,0)))
C34: 铸造铝合金 ad2607-ad2702合约 | G34: 0.1 | H34: =MAX(G34,N34+2%) -> 0.13 | I34: =MAX(G34,O34+2%) -> 0.15 | J34: 0.09 | K34: =MAX(J34,N34+2%) -> 0.13 | L34: =MAX(J34,O34+2%) -> 0.15 | M34: 0.08 | N34: =M34+3% -> 0.11 | O34: =N34+2% -> 0.13 | P34: =MAX(10%,G34) -> 0.1 | Q34: =MAX(10%,J34) -> 0.1 | R34: =MAX(15%,G34) -> 0.15 | S34: =MAX(15%,J34) -> 0.15 | T34: =MAX(20%,G34) -> 0.2 | U34: =MAX(J34,20%) -> 0.2
C35: 胶版印刷纸 | D35: op | E35: 40吨 | F35: 0.05 | G35: 0.07 | H35: =MAX(G35,N35+2%) -> 0.1 | I35: =MAX(G35,O35+2%) -> 0.12 | J35: 0.06 | K35: =MAX(J35,N35+2%) -> 0.1 | L35: =MAX(J35,O35+2%) -> 0.12 | M35: 0.05 | N35: =M35+3% -> 0.08 | O35: =N35+2% -> 0.1 | P35: =MAX(10%,G35) -> 0.1 | Q35: =MAX(10%,J35) -> 0.1 | R35: =MAX(15%,G35) -> 0.15 | S35: =MAX(15%,J35) -> 0.15 | T35: =MAX(20%,G35) -> 0.2 | U35: =MAX(J35,20%) -> 0.2 | V35: =IFERROR(IF(VLOOKUP(D35,期货合约要素!$D:$Q,12,0)=0,"",VLOOKUP(D35,期货合约要素!$D:$Q,12,0)),IF(VLOOKUP(D35,期权合约要素!$D:$V,17,0)=0,"",VLOOKUP(D35,期权合约要素!$D:$V,17,0))) | W35: =IFERROR(IF(VLOOKUP(D35,期货合约要素!$D:$Q,14,0)=0,"",VLOOKUP(D35,期货合约要素!$D:$Q,14,0)),IF(VLOOKUP(D35,期权合约要素!$D:$V,19,0)=0,"",VLOOKUP(D35,期权合约要素!$D:$V,19,0)))
C36: 保税380燃料油 | D36: fu | E36: 10吨 | F36: 0.13 | G36: 0.16 | H36: =MAX(G36,N36+2%) -> 0.19 | I36: =O36+2% -> 0.21 | J36: 0.15 | K36: =MAX(J36,N36+2%) -> 0.19 | L36: =MAX(J36,O36+2%) -> 0.21 | M36: 0.14 | N36: =M36+3% -> 0.17 | O36: =N36+2% -> 0.19 | P36: 交割月前2月第10个交易日起 （投机） | Q36: 交割月前2月第10个交易日起 （套保） | R36: 交割月前1月第10个交易日起 （投机） | S36: 交割月前1月第10个交易日起 （套保） | T36: 最后交易日前2个交易日起 （投机） | U36: 最后交易日前2个交易日起 （套保） | V36: =IFERROR(IF(VLOOKUP(D36,期货合约要素!$D:$Q,12,0)=0,"",VLOOKUP(D36,期货合约要素!$D:$Q,12,0)),IF(VLOOKUP(D36,期权合约要素!$D:$V,17,0)=0,"",VLOOKUP(D36,期权合约要素!$D:$V,17,0))) -> √ | W36: =IFERROR(IF(VLOOKUP(D36,期货合约要素!$D:$Q,14,0)=0,"",VLOOKUP(D36,期货合约要素!$D:$Q,14,0)),IF(VLOOKUP(D36,期权合约要素!$D:$V,19,0)=0,"",VLOOKUP(D36,期权合约要素!$D:$V,19,0)))
P37: =MAX(10%,G36) -> 0.16 | Q37: =MAX(10%,J36) -> 0.15 | R37: =MAX(15%,G36) -> 0.16 | S37: =MAX(15%,J36) -> 0.15 | T37: =MAX(20%,G36) -> 0.2 | U37: =MAX(J36,20%) -> 0.2
C38: 保税380燃料油 fu2607 | G38: 0.19 | H38: =MAX(G38,N38+2%) -> 0.22 | I38: =O38+2% -> 0.24 | J38: 0.18 | K38: =MAX(J38,N38+2%) -> 0.22 | L38: =MAX(J38,O38+2%) -> 0.24 | M38: 0.17 | N38: =M38+3% -> 0.2 | O38: =N38+2% -> 0.22 | P38: =MAX(10%,G38) -> 0.19 | Q38: =MAX(10%,J38) -> 0.18 | R38: =MAX(15%,G38) -> 0.19 | S38: =MAX(15%,J38) -> 0.18 | T38: =MAX(20%,G38) -> 0.2 | U38: =MAX(J38,20%) -> 0.2
B39: 上海国际能源交易中心 | C39: 20号胶 | D39: nr | E39: 10吨 | F39: 0.06 | G39: 0.09 | H39: =MAX(G39,N39+2%) -> 0.12 | I39: =MAX(G39,O39+2%) -> 0.14 | J39: 0.08 | K39: =MAX(J39,N39+2%) -> 0.12 | L39: =MAX(J39,O39+2%) -> 0.14 | M39: 0.07 | N39: =M39+3% -> 0.1 | O39: =N39+2% -> 0.12 | P39: 交割月前1月第1个交易日起 （投机） | Q39: 交割月前1月第1个交易日起 （套保） | R39: 交割月第1个交易日起 （投机） | S39: 交割月第1个交易日起 （套保） | T39: 最后交易日前2个交易日起 （投机） | U39: 最后交易日前2个交易日起 （套保） | V39: =IFERROR(IF(VLOOKUP(D39,期货合约要素!$D:$Q,12,0)=0,"",VLOOKUP(D39,期货合约要素!$D:$Q,12,0)),IF(VLOOKUP(D39,期权合约要素!$D:$V,17,0)=0,"",VLOOKUP(D39,期权合约要素!$D:$V,17,0))) -> √ | W39: =IFERROR(IF(VLOOKUP(D39,期货合约要素!$D:$Q,14,0)=0,"",VLOOKUP(D39,期货合约要素!$D:$Q,14,0)),IF(VLOOKUP(D39,期权合约要素!$D:$V,19,0)=0,"",VLOOKUP(D39,期权合约要素!$D:$V,19,0))) -> √
P40: =MAX(10%,G39) -> 0.1 | Q40: =MAX(10%,J39) -> 0.1 | R40: =MAX(15%,G39) -> 0.15 | S40: =MAX(15%,J40) -> 0.15 | T40: =MAX(20%,G39) -> 0.2 | U40: =MAX(J39,20%) -> 0.2
...

Sheet 限仓规则
A1: 点此返回目录
B2: 各交易所投机限仓标准（单边计算） | M2: 上交所股票期权限仓表
B3: 交易所 | C3: 品种名称 | D3: 品种代码 | E3: 合约挂牌至交割月前第二月的最后一个交易日 | G3: 交割月前第一月 | H3: 交割月份 | I3: 备注 | J3: QFII&RQFII | K3: 国际化品种 | M3: 投资者满足的条件 | N3: 权利仓持仓限额（张） | O3: 总持仓限额（张） | P3: 单日买入开仓限额（张） | Q3: 备注
B4: 上期所 | C4: 铝 | D4: al | E4: 市场单边持仓量≥10万手， 限仓比例10% | G4: 3000 | H4: 1000 | I4: 需调整为5手整数倍进入交割月 | J4: =IFERROR(IF(VLOOKUP(D4,期货合约要素!$D:$Q,12,0)=0,"",VLOOKUP(D4,期货合约要素!$D:$Q,12,0)),IF(VLOOKUP(D4,期权合约要素!$D:$V,17,0)=0,"",VLOOKUP(D4,期权合约要素!$D:$V,17,0))) -> √ | K4: =IFERROR(IF(VLOOKUP(D4,期货合约要素!$D:$Q,14,0)=0,"",VLOOKUP(D4,期货合约要素!$D:$Q,14,0)),IF(VLOOKUP(D4,期权合约要素!$D:$V,19,0)=0,"",VLOOKUP(D4,期权合约要素!$D:$V,19,0))) | M4: 新开立合约账户 | N4: 100 | O4: 200 | P4: 400 | Q4: 客户在多家经纪商开户的，各经纪商单独控制持仓限额。
E5: 市场单边持仓量＜10万手， 限仓10000 | J5: =IFERROR(IF(VLOOKUP(D5,期货合约要素!$D:$Q,12,0)=0,"",VLOOKUP(D5,期货合约要素!$D:$Q,12,0)),IF(VLOOKUP(D5,期权合约要素!$D:$V,17,0)=0,"",VLOOKUP(D5,期权合约要素!$D:$V,17,0))) -> #N/A | K5: =IFERROR(IF(VLOOKUP(D5,期货合约要素!$D:$Q,14,0)=0,"",VLOOKUP(D5,期货合约要素!$D:$Q,14,0)),IF(VLOOKUP(D5,期权合约要素!$D:$V,19,0)=0,"",VLOOKUP(D5,期权合约要素!$D:$V,19,0))) -> #N/A
C6: 铜 | D6: cu | E6: 市场单边持仓量≥8万手， 限仓比例10% | G6: 3000 | H6: 1000 | J6: =IFERROR(IF(VLOOKUP(D6,期货合约要素!$D:$Q,12,0)=0,"",VLOOKUP(D6,期货合约要素!$D:$Q,12,0)),IF(VLOOKUP(D6,期权合约要素!$D:$V,17,0)=0,"",VLOOKUP(D6,期权合约要素!$D:$V,17,0))) -> √ | K6: =IFERROR(IF(VLOOKUP(D6,期货合约要素!$D:$Q,14,0)=0,"",VLOOKUP(D6,期货合约要素!$D:$Q,14,0)),IF(VLOOKUP(D6,期权合约要素!$D:$V,19,0)=0,"",VLOOKUP(D6,期权合约要素!$D:$V,19,0))) | M6: （1）三级投资者 （2）开户满10个交易日 （3）成交量达到100张 | N6: 1000 | O6: 2000 | P6: 4000
E7: 市场单边持仓量＜8万手，限仓8000 | J7: =IFERROR(IF(VLOOKUP(D7,期货合约要素!$D:$Q,12,0)=0,"",VLOOKUP(D7,期货合约要素!$D:$Q,12,0)),IF(VLOOKUP(D7,期权合约要素!$D:$V,17,0)=0,"",VLOOKUP(D7,期权合约要素!$D:$V,17,0))) -> #N/A | K7: =IFERROR(IF(VLOOKUP(D7,期货合约要素!$D:$Q,14,0)=0,"",VLOOKUP(D7,期货合约要素!$D:$Q,14,0)),IF(VLOOKUP(D7,期权合约要素!$D:$V,19,0)=0,"",VLOOKUP(D7,期权合约要素!$D:$V,19,0))) -> #N/A
C8: 锌 | D8: zn | E8: 市场单边持仓量≥6万手， 限仓比例10% | G8: 2400 | H8: 800 | J8: =IFERROR(IF(VLOOKUP(D8,期货合约要素!$D:$Q,12,0)=0,"",VLOOKUP(D8,期货合约要素!$D:$Q,12,0)),IF(VLOOKUP(D8,期权合约要素!$D:$V,17,0)=0,"",VLOOKUP(D8,期权合约要素!$D:$V,17,0))) -> √ | K8: =IFERROR(IF(VLOOKUP(D8,期货合约要素!$D:$Q,14,0)=0,"",VLOOKUP(D8,期货合约要素!$D:$Q,14,0)),IF(VLOOKUP(D8,期权合约要素!$D:$V,19,0)=0,"",VLOOKUP(D8,期权合约要素!$D:$V,19,0)))
E9: 市场单边持仓量＜6万手， 限仓6000 | J9: =IFERROR(IF(VLOOKUP(D9,期货合约要素!$D:$Q,12,0)=0,"",VLOOKUP(D9,期货合约要素!$D:$Q,12,0)),IF(VLOOKUP(D9,期权合约要素!$D:$V,17,0)=0,"",VLOOKUP(D9,期权合约要素!$D:$V,17,0))) -> #N/A | K9: =IFERROR(IF(VLOOKUP(D9,期货合约要素!$D:$Q,14,0)=0,"",VLOOKUP(D9,期货合约要素!$D:$Q,14,0)),IF(VLOOKUP(D9,期权合约要素!$D:$V,19,0)=0,"",VLOOKUP(D9,期权合约要素!$D:$V,19,0))) -> #N/A | M9: （1）三级投资者 （2）开户满10个交易日 （3）成交量达到500张 （4）在我司托管的自有资产余额超过100万 | N9: 2000 | O9: 4000 | P9: 8000
C10: 铅 | D10: pb | E10: 市场单边持仓量≥5万手， 限仓比例10% | G10: 1800 | H10: 600 | J10: =IFERROR(IF(VLOOKUP(D10,期货合约要素!$D:$Q,12,0)=0,"",VLOOKUP(D10,期货合约要素!$D:$Q,12,0)),IF(VLOOKUP(D10,期权合约要素!$D:$V,17,0)=0,"",VLOOKUP(D10,期权合约要素!$D:$V,17,0))) -> √ | K10: =IFERROR(IF(VLOOKUP(D10,期货合约要素!$D:$Q,14,0)=0,"",VLOOKUP(D10,期货合约要素!$D:$Q,14,0)),IF(VLOOKUP(D10,期权合约要素!$D:$V,19,0)=0,"",VLOOKUP(D10,期权合约要素!$D:$V,19,0)))
E11: 市场单边持仓量＜5万手，限仓5000 | J11: =IFERROR(IF(VLOOKUP(D11,期货合约要素!$D:$Q,12,0)=0,"",VLOOKUP(D11,期货合约要素!$D:$Q,12,0)),IF(VLOOKUP(D11,期权合约要素!$D:$V,17,0)=0,"",VLOOKUP(D11,期权合约要素!$D:$V,17,0))) -> #N/A | K11: =IFERROR(IF(VLOOKUP(D11,期货合约要素!$D:$Q,14,0)=0,"",VLOOKUP(D11,期货合约要素!$D:$Q,14,0)),IF(VLOOKUP(D11,期权合约要素!$D:$V,19,0)=0,"",VLOOKUP(D11,期权合约要素!$D:$V,19,0))) -> #N/A
C12: 螺纹钢 | D12: rb | E12: 市场单边持仓量≥90万手，限仓比例10% | G12: 4500 | H12: 900 | I12: 需调整为30手整数倍进入交割月 | J12: =IFERROR(IF(VLOOKUP(D12,期货合约要素!$D:$Q,12,0)=0,"",VLOOKUP(D12,期货合约要素!$D:$Q,12,0)),IF(VLOOKUP(D12,期权合约要素!$D:$V,17,0)=0,"",VLOOKUP(D12,期权合约要素!$D:$V,17,0))) -> √ | K12: =IFERROR(IF(VLOOKUP(D12,期货合约要素!$D:$Q,14,0)=0,"",VLOOKUP(D12,期货合约要素!$D:$Q,14,0)),IF(VLOOKUP(D12,期权合约要素!$D:$V,19,0)=0,"",VLOOKUP(D12,期权合约要素!$D:$V,19,0)))
E13: 市场单边持仓量＜90万手，限仓90000 | J13: =IFERROR(IF(VLOOKUP(D13,期货合约要素!$D:$Q,12,0)=0,"",VLOOKUP(D13,期货合约要素!$D:$Q,12,0)),IF(VLOOKUP(D13,期权合约要素!$D:$V,17,0)=0,"",VLOOKUP(D13,期权合约要素!$D:$V,17,0))) -> #N/A | K13: =IFERROR(IF(VLOOKUP(D13,期货合约要素!$D:$Q,14,0)=0,"",VLOOKUP(D13,期货合约要素!$D:$Q,14,0)),IF(VLOOKUP(D13,期权合约要素!$D:$V,19,0)=0,"",VLOOKUP(D13,期权合约要素!$D:$V,19,0))) -> #N/A | M13: （1）三级投资者 （2）开户满10个交易日 （3）成交量达到1000张 （4）在我司托管的自有资产余额超过300万 （须先向上交所报备，下一交易日设置） | N13: 5000 | O13: 10000 | P13: 10000
C14: 线材 | D14: wr | E14: 市场单边持仓量≥22.5万手， 限仓比例10% | G14: 1800 | H14: 360 | J14: =IFERROR(IF(VLOOKUP(D14,期货合约要素!$D:$Q,12,0)=0,"",VLOOKUP(D14,期货合约要素!$D:$Q,12,0)),IF(VLOOKUP(D14,期权合约要素!$D:$V,17,0)=0,"",VLOOKUP(D14,期权合约要素!$D:$V,17,0))) | K14: =IFERROR(IF(VLOOKUP(D14,期货合约要素!$D:$Q,14,0)=0,"",VLOOKUP(D14,期货合约要素!$D:$Q,14,0)),IF(VLOOKUP(D14,期权合约要素!$D:$V,19,0)=0,"",VLOOKUP(D14,期权合约要素!$D:$V,19,0)))
E15: 市场单边持仓量＜22.5万手，限仓22500 | J15: =IFERROR(IF(VLOOKUP(D15,期货合约要素!$D:$Q,12,0)=0,"",VLOOKUP(D15,期货合约要素!$D:$Q,12,0)),IF(VLOOKUP(D15,期权合约要素!$D:$V,17,0)=0,"",VLOOKUP(D15,期权合约要素!$D:$V,17,0))) -> #N/A | K15: =IFERROR(IF(VLOOKUP(D15,期货合约要素!$D:$Q,14,0)=0,"",VLOOKUP(D15,期货合约要素!$D:$Q,14,0)),IF(VLOOKUP(D15,期权合约要素!$D:$V,19,0)=0,"",VLOOKUP(D15,期权合约要素!$D:$V,19,0))) -> #N/A
C16: 热卷 | D16: hc | E16: 市场单边持仓量≥120万手， 限仓比例10% | G16: 9000 | H16: 1800 | J16: =IFERROR(IF(VLOOKUP(D16,期货合约要素!$D:$Q,12,0)=0,"",VLOOKUP(D16,期货合约要素!$D:$Q,12,0)),IF(VLOOKUP(D16,期权合约要素!$D:$V,17,0)=0,"",VLOOKUP(D16,期权合约要素!$D:$V,17,0))) -> √ | K16: =IFERROR(IF(VLOOKUP(D16,期货合约要素!$D:$Q,14,0)=0,"",VLOOKUP(D16,期货合约要素!$D:$Q,14,0)),IF(VLOOKUP(D16,期权合约要素!$D:$V,19,0)=0,"",VLOOKUP(D16,期权合约要素!$D:$V,19,0)))
E17: 市场单边持仓量＜120万手，限仓120000 | J17: =IFERROR(IF(VLOOKUP(D17,期货合约要素!$D:$Q,12,0)=0,"",VLOOKUP(D17,期货合约要素!$D:$Q,12,0)),IF(VLOOKUP(D17,期权合约要素!$D:$V,17,0)=0,"",VLOOKUP(D17,期权合约要素!$D:$V,17,0))) -> #N/A | K17: =IFERROR(IF(VLOOKUP(D17,期货合约要素!$D:$Q,14,0)=0,"",VLOOKUP(D17,期货合约要素!$D:$Q,14,0)),IF(VLOOKUP(D17,期权合约要素!$D:$V,19,0)=0,"",VLOOKUP(D17,期权合约要素!$D:$V,19,0))) -> #N/A
C18: 氧化铝 | D18: ao | E18: 8000 | G18: 900 | H18: 300 | I18: 需调整为15手整数倍进入交割月 | J18: =IFERROR(IF(VLOOKUP(D18,期货合约要素!$D:$Q,12,0)=0,"",VLOOKUP(D18,期货合约要素!$D:$Q,12,0)),IF(VLOOKUP(D18,期权合约要素!$D:$V,17,0)=0,"",VLOOKUP(D18,期权合约要素!$D:$V,17,0))) | K18: =IFERROR(IF(VLOOKUP(D18,期货合约要素!$D:$Q,14,0)=0,"",VLOOKUP(D18,期货合约要素!$D:$Q,14,0)),IF(VLOOKUP(D18,期权合约要素!$D:$V,19,0)=0,"",VLOOKUP(D18,期权合约要素!$D:$V,19,0)))
C19: 不锈钢 | D19: ss | E19: 市场单边持仓量≥7万手， 限仓比例10% | G19: 1800 | H19: 360 | I19: 需调整为12手整数倍进入交割月 | J19: =IFERROR(IF(VLOOKUP(D19,期货合约要素!$D:$Q,12,0)=0,"",VLOOKUP(D19,期货合约要素!$D:$Q,12,0)),IF(VLOOKUP(D19,期权合约要素!$D:$V,17,0)=0,"",VLOOKUP(D19,期权合约要素!$D:$V,17,0))) -> √ | K19: =IFERROR(IF(VLOOKUP(D19,期货合约要素!$D:$Q,14,0)=0,"",VLOOKUP(D19,期货合约要素!$D:$Q,14,0)),IF(VLOOKUP(D19,期权合约要素!$D:$V,19,0)=0,"",VLOOKUP(D19,期权合约要素!$D:$V,19,0)))
E20: 市场单边持仓量＜7万手，限仓7000 | J20: =IFERROR(IF(VLOOKUP(D20,期货合约要素!$D:$Q,12,0)=0,"",VLOOKUP(D20,期货合约要素!$D:$Q,12,0)),IF(VLOOKUP(D20,期权合约要素!$D:$V,17,0)=0,"",VLOOKUP(D20,期权合约要素!$D:$V,17,0))) -> #N/A | K20: =IFERROR(IF(VLOOKUP(D20,期货合约要素!$D:$Q,14,0)=0,"",VLOOKUP(D20,期货合约要素!$D:$Q,14,0)),IF(VLOOKUP(D20,期权合约要素!$D:$V,19,0)=0,"",VLOOKUP(D20,期权合约要素!$D:$V,19,0))) -> #N/A
C21: 镍 | D21: ni | E21: 市场单边持仓量≥6万手， 限仓比例10% | G21: 1800 | H21: 600 | I21: 需调整为6手整数倍进入交割月 | J21: =IFERROR(IF(VLOOKUP(D21,期货合约要素!$D:$Q,12,0)=0,"",VLOOKUP(D21,期货合约要素!$D:$Q,12,0)),IF(VLOOKUP(D21,期权合约要素!$D:$V,17,0)=0,"",VLOOKUP(D21,期权合约要素!$D:$V,17,0))) -> √ | K21: =IFERROR(IF(VLOOKUP(D21,期货合约要素!$D:$Q,14,0)=0,"",VLOOKUP(D21,期货合约要素!$D:$Q,14,0)),IF(VLOOKUP(D21,期权合约要素!$D:$V,19,0)=0,"",VLOOKUP(D21,期权合约要素!$D:$V,19,0))) -> √ | M21: 深交所股票期权限仓表
E22: 市场单边持仓量＜6万手，限仓6000 | J22: =IFERROR(IF(VLOOKUP(D22,期货合约要素!$D:$Q,12,0)=0,"",VLOOKUP(D22,期货合约要素!$D:$Q,12,0)),IF(VLOOKUP(D22,期权合约要素!$D:$V,17,0)=0,"",VLOOKUP(D22,期权合约要素!$D:$V,17,0))) -> #N/A | K22: =IFERROR(IF(VLOOKUP(D22,期货合约要素!$D:$Q,14,0)=0,"",VLOOKUP(D22,期货合约要素!$D:$Q,14,0)),IF(VLOOKUP(D22,期权合约要素!$D:$V,19,0)=0,"",VLOOKUP(D22,期权合约要素!$D:$V,19,0))) -> #N/A | M22: 投资者满足的条件 | N22: 权利仓持仓限额（张） | O22: 总持仓限额（张） | P22: 单日买入开仓限额（张） | Q22: 备注
